Workbook

Sheet Cover & Assumptions
B2: Connect Biopharma Holdings Limited (NASDAQ: CNTB)
B3: Rademikibart (anti-IL-4Rα mAb) — Acute Exacerbations of Asthma & COPD | Working Valuation & Diligence File
B4: Prepared as an ongoing analyst working file. All figures in USD unless noted. Blue = input/hardcode. Black = formula. Green = link to another tab.
B6: Data as-of date: | C6: 1-Jul-2026 (price/mkt data); 31-Mar-2026 (balance sheet, 10-Q)
B7: Ticker / Exchange: | C7: CNTB / Nasdaq Global Market
B8: Lead asset: | C8: Rademikibart (anti-IL-4Rα mAb)
B10: Current Share Price ($) | C10: 2.4 | G10: Source: StockAnalysis.com / Morningstar, intraday ~$2.35-2.45 late Jun/1-Jul 2026. Stock is highly volatile (52-wk range $1.23-$3.82) — UPDATE before relying on this file.
B11: Shares Outstanding, basic (mm) | C11: 62.7117 | G11: CORRECTED to the exact figure on the 10-Q balance sheet: 62,711,690 ordinary shares issued and outstanding as of 31-Mar-2026 (vs. 56,442,308 at 31-Dec-2025). Source: cntb-20260331.html.
B12: Est. Fully-Diluted Shares (mm) | C12: 78.48 | G12: RESOLVED from the actual 10-Q (Note on Net Loss per Share, anti-dilutive securities table): 15,167,637 stock options outstanding (weighted-avg exercise price $2.08 - meaningfully in-the-money at the current ~$2.40 share price) plus 600,000 employee stock purchase plan rights, on top of 62.7117mm basic shares = ~78.48mm on a simple if-exercised gross basis (62.7117 + 15.1676 + 0.60). Note this is a gross, not treasury-method-reduced, fully-diluted count - the treasury-stock-method diluted EPS count would be lower because option-exercise proceeds would notionally repurchase some shares, but for valuation (not EPS) purposes the gross if-exercised count is the more standard convention. Source: cntb-20260331.html, Note on Net Loss per Share.
B13: Market Cap, basic ($mm) | C13: =C10*C11 -> 150.50808
B14: 52-Week Range ($) | C14: 1.23 - 3.82
B15: Cash, Equiv. & ST Investments ($mm) | C15: ='Balance Sheet & Cash Runway'!C9 -> 52.031
B16: Total Debt ($mm) | C16: ='Balance Sheet & Cash Runway'!C11 -> 0
B17: Enterprise Value, basic shares ($mm) | C17: =C13-C15+C16 -> 98.47708 | G17: EV is negative at the current price/cash level — a common feature of clinical-stage biotech trading near or below net cash, and worth flagging as either deep value or a market signal on program risk.
A19: PROGRAM STATUS & PIPELINE
B21: Program 1 — US/global: | C21: Ph2 SEABREEZE STAT Asthma (n=160, acute exacerbations, EOS≥300); enrollment complete 17-Jun-2026; primary endpoint = 28-day treatment-failure rate; key secondary = post-BD FEV1 at Wk1. | G21: Topline expected early Sept 2026 (company guidance, 17-Jun-2026 PR).
B22: Program 2 — US/global: | C22: Ph2 SEABREEZE STAT COPD (n=160, acute exacerbations, EOS≥300); enrollment substantially complete ~Jun 2026. | G22: Topline expected shortly after Asthma readout — company has not given a firm date; we ESTIMATE Q4 2026.
B23: Supportive data: | C23: Prior global Ph2 chronic moderate-to-severe asthma trial (positive, published AJRCCM) + Ph1 IV rademikibart (rapid FEV1 improvement within 24h, sustained through ~4 wks). | G23: Completed; de-risks mechanism, not the acute-exacerbation endpoint specifically.
B24: China (Simcere license): | C24: Simcere holds exclusive Greater-China rights to rademikibart, all indications (signed 21-Nov-2023). Deal economics per the actual Q1'26 10-Q: $21mm upfront (2023); total milestones originally up to $123mm; $5mm received in 2024; ~$8mm LAPSED in 2025 (a time-based milestone Simcere missed the deadline for - a real, already-materialized execution-risk event, not a hypothetical); $110mm remaining eligible milestones; tiered low-double-digit royalties on Greater China net sales for ~12 years post-commercialization. China Ph3 AD trial met all endpoints; NDA submitted to China's regulator. | G24: UPDATED with exact figures from cntb-20260331.html (10-Q Note 8, License and Collaboration Agreement) - materially more precise and complete than our original secondary-source summary, and importantly reveals the $8mm lapsed milestone as a real precedent for Simcere-side execution risk.
B25: DMC interim review: | C25: Independent DMC completed pre-specified interim efficacy review of both SEABREEZE STAT studies (23-Apr-2026): no safety concerns, no change to sample size recommended. | G25: Positive procedural signal; not a read on efficacy magnitude.
A27: KEY UPCOMING CATALYSTS / DATES
B29: Q2 2026 earnings | C29: 12-Aug-2026 | G29: Confirmed (StockAnalysis.com earnings calendar).
B30: SEABREEZE STAT Asthma topline | C30: Early Sept 2026 | G30: Company guidance, 17-Jun-2026 press release.
B31: SEABREEZE STAT COPD topline | C31: Q4 2026 (EST.) | G31: ESTIMATE — company says 'shortly after' asthma; no firm date given.
B32: FDA Phase 3 alignment meeting | C32: H2 2026 / H1 2027 (EST.) | G32: ESTIMATE — company states intent to 'move quickly' post-data; no confirmed date.
B33: Cash runway (per management) | C33: Into 2H 2027 | G33: Per Q1'26 10-Q / 8-K, based on current operating plan; excludes any new financing.
A35: SCENARIO SELECTOR
B37: Active scenario (drives every downstream tab): | C37: Base | G37: Change this cell to Low / Base / High — every assumption below, and the rNPV/DCF/relative-valuation tabs, re-flow automatically.
A39: MASTER ASSUMPTIONS (Low / Base / High, with Selected value flowing downstream)
B41: Assumption | C41: Low | D41: Base | E41: High | F41: Selected | G41: Source / Basis
B42: PoS: SEABREEZE Asthma Ph2 — positive topline | C42: 0.4 | D42: 0.6 | E42: 0.75 | F42: =IF($C$37="Low",C42,IF($C$37="Base",D42,E42)) -> 0.6 | G42: ESTIMATE/JUDGMENT. Mechanism de-risked by validated IL-4Rα target (Dupixent), positive Ph1 IV & prior chronic-asthma Ph2 (AJRCCM), and a clean DMC interim review — but the acute-exacerbation endpoint (28-day treatment failure) has not been tested for this mechanism before. Treat as a genuine binary-risk estimate, not a fact.
B43: PoS: Ph2(+)→US Approval, Asthma (execution+FDA risk) | C43: 0.35 | D43: 0.5 | E43: 0.65 | F43: =IF($C$37="Low",C43,IF($C$37="Base",D43,E43)) -> 0.5 | G43: ESTIMATE. Reflects typical Ph2→approval conversion for validated-MOA respiratory biologics (industry base rates for Ph2 immunology assets run ~30-55%).
B44: PoS: US Approval, COPD (own binary + asthma read-through) | C44: 0.18 | D44: 0.28 | E44: 0.4 | F44: =IF($C$37="Low",C44,IF($C$37="Base",D44,E44)) -> 0.28 | G44: ESTIMATE — COPD approval history for Th2/IL-4 biologics is mixed and slower (e.g., Dupixent's COPD approval came years after asthma, in a narrower population). We discount COPD below asthma for this reason.
B45: US peak eligible patients — Asthma (000s/yr) | C45: 350 | D45: 450 | E45: 550 | F45: =IF($C$37="Low",C45,IF($C$37="Base",D45,E45)) -> 450 | G45: Bottom-up: company discloses >1mm US ED visits/yr for acute asthma exacerbation; we apply ~35-55% for EOS≥300/FeNO≥25 (biomarker-eligible) and net for repeat-visit patients. GENUINE ESTIMATE — no third-party epi study cited by company.
B46: US peak eligible patients — COPD (000s/yr) | C46: 400 | D46: 550 | E46: 700 | F46: =IF($C$37="Low",C46,IF($C$37="Base",D46,E46)) -> 550 | G46: Bottom-up: CDC-cited ~1.5mm annual US COPD-exacerbation hospitalizations/ED visits; ESTIMATE ~35-50% EOS≥300 eligible, netted for repeat visits.
B47: Net price per treated patient per year ($) | C47: 6000 | D47: 9000 | E47: 13000 | F47: =IF($C$37="Low",C47,IF($C$37="Base",D47,E47)) -> 9000 | G47: UNKNOWN / GENUINE ESTIMATE — company has given no pricing guidance. Proxy: episodic/acute specialty-biologic pricing analogues, net of gross-to-net. This is the single largest swing factor in the model.
B48: Peak penetration of eligible population | C48: 0.12 | D48: 0.2 | E48: 0.3 | F48: =IF($C$37="Low",C48,IF($C$37="Base",D48,E48)) -> 0.2 | G48: ESTIMATE. No approved biologic exists in the acute-exacerbation setting today (differentiated), but point-of-care/ED biologic administration is a novel commercial model with real adoption-curve risk.
B49: US launch year — Asthma | C49: 2032 | D49: 2031 | E49: 2030 | F49: =IF($C$37="Low",C49,IF($C$37="Base",D49,E49)) -> 2031 | G49: ESTIMATE from data timing: Ph2 data Sep-2026 (Base) → ~2yr Ph3 → filing/review. High = faster path (e.g., breakthrough designation); Low = slower.
B50: US launch year — COPD | C50: 2033 | D50: 2032 | E50: 2031 | F50: =IF($C$37="Low",C50,IF($C$37="Base",D50,E50)) -> 2032 | G50: ESTIMATE — assumes ~1yr behind Asthma given later Ph2 data and typically slower COPD regulatory path.
B51: Years from launch to peak sales | C51: 6 | D51: 5 | E51: 4 | F51: =IF($C$37="Low",C51,IF($C$37="Base",D51,E51)) -> 5 | G51: ESTIMATE — typical biologic launch curve in a new site-of-care (ED/urgent care) commercial model.
...

Sheet Balance Sheet & Cash Runway
B2: Balance Sheet & Cash Runway
B3: Source: Form 10-Q for the quarter ended 31-Mar-2026 (filed 12-May-2026) + 30-Mar-2026 private placement 8-K. Cash items below are the last reported balance sheet; UPDATE each quarter.
A5: CASH POSITION (as of 31-Mar-2026, $mm)
B7: Cash and cash equivalents | C7: 46.034 | G7: CORRECTED from actual 10-Q balance sheet (period 31-Mar-2026): cash and cash equivalents = $46.034mm. Prior version of this file wrongly split a secondary source's headline '$46.0mm' figure between this line and the one below - the $46.0mm figure in press summaries is actually just this cash-and-equivalents line, not the total.
B8: Short-term investments | C8: 5.997 | G8: CORRECTED from actual 10-Q balance sheet: short-term investments = $5.997mm, additive to cash and equivalents above (total liquidity $52.03mm, not $46.0mm as press summaries implied).
B9: Total cash, cash equivalents & ST investments | C9: =C7+C8 -> 52.031 | G9: Now ties to the actual 10-Q balance sheet total: $46.034mm + $5.997mm = $52.03mm as of 31-Mar-2026 (source: cntb-20260331.html, Condensed Consolidated Balance Sheets).
B11: Total debt | C11: 0 | G11: Company reported zero debt as of the last balance sheet (Simply Wall St / 10-Q). No covenants, tranching, or maturity schedule to disclose — capital structure is currently all-equity.
A13: RECENT FINANCING & DILUTION
B15: 30-Mar-2026 private placement — gross proceeds ($mm) | C15: 20.2 | G15: 6,130,000 ordinary shares at $3.25/share to new & existing investors. Closed 31-Mar-2026.
B16: 30-Mar-2026 private placement — est. net proceeds ($mm) | C16: 18.6 | G16: Per company release; ~8% placement/legal costs implied.
B17: Director open-market buy, 29-May-2026 ($mm) | C17: 0.37 | G17: Director James Huang bought 150,000 sh @ $2.48 — open-market, i.e., a real conviction signal (not options/RSU mechanics).
B18: Panacea Venture (largest shareholder) PIPE lead, 31-Mar-2026 ($mm) | C18: 4 | G18: CORRECTED / IMPORTANT: per 10-Q Note 9 (Shareholders' Equity), this $4.0mm was NOT a generic director PIPE participation - it was purchased by Panacea Venture, described in the filing as 'the Company's largest current investor,' which LED the entire March 2026 private placement. Board member James Huang is the sole owner of Panacea Innovation Limited, which is the sole owner of Panacea Venture. This is therefore a related-party transaction: the company's largest shareholder (controlled by a sitting director) anchored its own financing round. Read this as a genuinely stronger commitment-of-capital signal than ordinary PIPE participation (the largest holder underwriting the raise), but also flag the governance question a related-party-led financing always raises (were the $3.25/share terms arm's-length; how was the transaction approved). We do not have Panacea Venture's TOTAL stake size (beyond this incremental $4.0mm) from this 10-Q - that would need a Schedule 13D/G filing, which we recommend pulling next, since Panacea Venture is arguably the single most important ownership fact in the file and was not captured in our earlier institutional-holder research.
A20: SHARE COUNT — BASIC VS. FULLY DILUTED
B22: Ordinary shares outstanding, basic (mm) | C22: 62.7117 | G22: CORRECTED to exact 10-Q figure: 62,711,690 shares as of 31-Mar-2026.
B23: Q1 2026 weighted-avg shares, basic & diluted (mm) | C23: 56.545 | G23: CORRECTED to exact 10-Q figure: weighted-avg basic & diluted shares, three months ended 31-Mar-2026 = 56,545,000.
B24: Stock options outstanding (mm), wtd-avg strike $2.08 | C24: 15.1676 | G24: SOURCED (was previously an unknown placeholder). Per 10-Q Note 10 (Equity Incentive Plans): 15,167,637 options outstanding at 31-Mar-2026, weighted-average exercise price $2.08 - i.e. in-the-money at the current share price, real near-term dilution risk, not a distant hypothetical. Separately, 600,000 employee stock purchase plan rights are also outstanding (anti-dilutive table). Source: cntb-20260331.html.
A26: BURN RATE & CASH RUNWAY
B28: Q1 2026 R&D expense ($mm) | C28: 15.03 | G28: Source: Q1 2026 10-Q / 8-K (filed 12-May-2026). R&D more than doubled y/y as SEABREEZE STAT enrollment ramped; net loss widened to $19.4mm ($0.34/sh) from $10.3mm ($0.19/sh) in Q1 2025.
B29: Q1 2026 G&A expense ($mm) | C29: 4.746
B30: Q1 2026 license/collaboration revenue ($mm) | C30: 0.169
B31: Q1 2026 net loss ($mm) | C31: 19.398 | G31: Exact 10-Q figure: net loss $19,398 thousand = $19.398mm ($0.34/share), vs. $10,272 thousand ($0.19/share) in Q1 2025. Includes $48K income tax expense.
B32: Q1 2026 operating cash outflow ($mm) | C32: 16
B33: Assumed steady-state quarterly cash burn, next 12mo ($mm) | C33: =C32*1.05 -> 16.8 | G33: ESTIMATE: Q1'26 actual op. cash outflow +5%, reflecting COPD enrollment completion and ramp toward two Ph2 data readouts. Update once Q2 2026 10-Q (due ~12-Aug-2026) is out.
B35: Implied quarters of runway from current cash | C35: ='Cover & Assumptions'!C15/C33 -> 3.0970833
B36: Implied runway exhaustion (quarter-end basis) | C36: =EDATE(DATE(2026,3,31),3*C35) -> 46387 | G36: UPDATED: the 10-Q's formal Liquidity & Going Concern note (Note 2) only commits to cash being sufficient for 'at least one year from the date this Quarterly Report is filed' - filed 12-May-2026, i.e. through at least ~12-May-2027. The looser 'into 2H 2027' framing comes from press-release/8-K language, not this more conservative formal disclosure. Treat ~May-2027 as the company's actual legal commitment and '2H 2027' as aspirational guidance on top of it.
A38: FINANCING NEED / DILUTION RISK FLAG
B40: SEABREEZE STAT data (Sept 2026) precedes the low end of the mechanical runway estimate. If both readouts are positive, CNTB will almost certainly need to raise capital to fund a Phase 3 program — likely via a follow-on equity raise, a royalty/synthetic-royalty deal (as Apogee Therapeutics did with AbbVie/undisclosed lender), or a Simcere-style ex-China licensing deal. Any of these is dilutive or cash-flow-negative in the near term and should be modeled explicitly once terms are known — none are in this file yet.

Sheet rNPV Model
B2: rNPV Model — Rademikibart, Acute Exacerbations of Asthma & COPD
B3: Bottom-up, epidemiology-driven, probability-of-success risk-adjusted. This should be the most conservative, defensible number in the file — every unrisked dollar here is explicitly discounted by the odds of getting there.
B5: Fiscal Year | C5: 2026 | D5: 2027 | E5: 2028 | F5: 2029 | G5: 2030 | H5: 2031 | I5: 2032 | J5: 2033 | K5: 2034 | L5: 2035 | M5: 2036 | N5: 2037 | O5: 2038 | P5: 2039 | Q5: 2040 | R5: 2041 | S5: 2042 | T5: 2043 | U5: 2044 | V5: 2045
A7: PROGRAM 1 — ACUTE EXACERBATIONS OF ASTHMA (US)
B9: Years since launch | C9: =C$5-'Cover & Assumptions'!$F$49 -> -5 | D9: =D$5-'Cover & Assumptions'!$F$49 -> -4 | E9: =E$5-'Cover & Assumptions'!$F$49 -> -3 | F9: =F$5-'Cover & Assumptions'!$F$49 -> -2 | G9: =G$5-'Cover & Assumptions'!$F$49 -> -1 | H9: =H$5-'Cover & Assumptions'!$F$49 -> 0 | I9: =I$5-'Cover & Assumptions'!$F$49 -> 1 | J9: =J$5-'Cover & Assumptions'!$F$49 -> 2 | ... V9: =V$5-'Cover & Assumptions'!$F$49 -> 14
B10: Penetration of eligible population | C10: =IF(C9<0,0,IF(C9>='Cover & Assumptions'!$F$52-'Cover & Assumptions'!$F$49,'Cover & Assumptions'!$F$48*0.15,MIN('Cover & Assumptions'!$F$48,'Cover & Assumptions'!$F$48*C9/'Cover & Assumptions'!$F$51))) -> 0 | D10: =IF(D9<0,0,IF(D9>='Cover & Assumptions'!$F$52-'Cover & Assumptions'!$F$49,'Cover & Assumptions'!$F$48*0.15,MIN('Cover & Assumptions'!$F$48,'Cover & Assumptions'!$F$48*D9/'Cover & Assumptions'!$F$51))) -> 0 | E10: =IF(E9<0,0,IF(E9>='Cover & Assumptions'!$F$52-'Cover & Assumptions'!$F$49,'Cover & Assumptions'!$F$48*0.15,MIN('Cover & Assumptions'!$F$48,'Cover & Assumptions'!$F$48*E9/'Cover & Assumptions'!$F$51))) -> 0 | F10: =IF(F9<0,0,IF(F9>='Cover & Assumptions'!$F$52-'Cover & Assumptions'!$F$49,'Cover & Assumptions'!$F$48*0.15,MIN('Cover & Assumptions'!$F$48,'Cover & Assumptions'!$F$48*F9/'Cover & Assumptions'!$F$51))) -> 0 | G10: =IF(G9<0,0,IF(G9>='Cover & Assumptions'!$F$52-'Cover & Assumptions'!$F$49,'Cover & Assumptions'!$F$48*0.15,MIN('Cover & Assumptions'!$F$48,'Cover & Assumptions'!$F$48*G9/'Cover & Assumptions'!$F$51))) -> 0 | H10: =IF(H9<0,0,IF(H9>='Cover & Assumptions'!$F$52-'Cover & Assumptions'!$F$49,'Cover & Assumptions'!$F$48*0.15,MIN('Cover & Assumptions'!$F$48,'Cover & Assumptions'!$F$48*H9/'Cover & Assumptions'!$F$51))) -> 0 | I10: =IF(I9<0,0,IF(I9>='Cover & Assumptions'!$F$52-'Cover & Assumptions'!$F$49,'Cover & Assumptions'!$F$48*0.15,MIN('Cover & Assumptions'!$F$48,'Cover & Assumptions'!$F$48*I9/'Cover & Assumptions'!$F$51))) -> 0.04 | J10: =IF(J9<0,0,IF(J9>='Cover & Assumptions'!$F$52-'Cover & Assumptions'!$F$49,'Cover & Assumptions'!$F$48*0.15,MIN('Cover & Assumptions'!$F$48,'Cover & Assumptions'!$F$48*J9/'Cover & Assumptions'!$F$51))) -> 0.08 | ... V10: =IF(V9<0,0,IF(V9>='Cover & Assumptions'!$F$52-'Cover & Assumptions'!$F$49,'Cover & Assumptions'!$F$48*0.15,MIN('Cover & Assumptions'!$F$48,'Cover & Assumptions'!$F$48*V9/'Cover & Assumptions'!$F$51))) -> 0.03
B11: Treated patients (000s) | C11: ='Cover & Assumptions'!$F$45*C10 -> 0 | D11: ='Cover & Assumptions'!$F$45*D10 -> 0 | E11: ='Cover & Assumptions'!$F$45*E10 -> 0 | F11: ='Cover & Assumptions'!$F$45*F10 -> 0 | G11: ='Cover & Assumptions'!$F$45*G10 -> 0 | H11: ='Cover & Assumptions'!$F$45*H10 -> 0 | I11: ='Cover & Assumptions'!$F$45*I10 -> 18 | J11: ='Cover & Assumptions'!$F$45*J10 -> 36 | ... V11: ='Cover & Assumptions'!$F$45*V10 -> 13.5
B12: Unrisked US net revenue ($mm) | C12: =C11*1000*'Cover & Assumptions'!$F$47/1000000 -> 0 | D12: =D11*1000*'Cover & Assumptions'!$F$47/1000000 -> 0 | E12: =E11*1000*'Cover & Assumptions'!$F$47/1000000 -> 0 | F12: =F11*1000*'Cover & Assumptions'!$F$47/1000000 -> 0 | G12: =G11*1000*'Cover & Assumptions'!$F$47/1000000 -> 0 | H12: =H11*1000*'Cover & Assumptions'!$F$47/1000000 -> 0 | I12: =I11*1000*'Cover & Assumptions'!$F$47/1000000 -> 162 | J12: =J11*1000*'Cover & Assumptions'!$F$47/1000000 -> 324 | ... V12: =V11*1000*'Cover & Assumptions'!$F$47/1000000 -> 121.5
B13: COGS ($mm) | C13: =-C12*'Cover & Assumptions'!$F$53 -> 0 | D13: =-D12*'Cover & Assumptions'!$F$53 -> 0 | E13: =-E12*'Cover & Assumptions'!$F$53 -> 0 | F13: =-F12*'Cover & Assumptions'!$F$53 -> 0 | G13: =-G12*'Cover & Assumptions'!$F$53 -> 0 | H13: =-H12*'Cover & Assumptions'!$F$53 -> 0 | I13: =-I12*'Cover & Assumptions'!$F$53 -> -24.3 | J13: =-J12*'Cover & Assumptions'!$F$53 -> -48.6 | ... V13: =-V12*'Cover & Assumptions'!$F$53 -> -18.225
B14: SG&A ($mm) | C14: =IF(AND(C9<0,C9>=-2),-8,IF(C12>0,-C12*'Cover & Assumptions'!$F$54,0)) -> 0 | D14: =IF(AND(D9<0,D9>=-2),-8,IF(D12>0,-D12*'Cover & Assumptions'!$F$54,0)) -> 0 | E14: =IF(AND(E9<0,E9>=-2),-8,IF(E12>0,-E12*'Cover & Assumptions'!$F$54,0)) -> 0 | F14: =IF(AND(F9<0,F9>=-2),-8,IF(F12>0,-F12*'Cover & Assumptions'!$F$54,0)) -> -8 | G14: =IF(AND(G9<0,G9>=-2),-8,IF(G12>0,-G12*'Cover & Assumptions'!$F$54,0)) -> -8 | H14: =IF(AND(H9<0,H9>=-2),-8,IF(H12>0,-H12*'Cover & Assumptions'!$F$54,0)) -> 0 | I14: =IF(AND(I9<0,I9>=-2),-8,IF(I12>0,-I12*'Cover & Assumptions'!$F$54,0)) -> -45.36 | J14: =IF(AND(J9<0,J9>=-2),-8,IF(J12>0,-J12*'Cover & Assumptions'!$F$54,0)) -> -90.72 | ... V14: =IF(AND(V9<0,V9>=-2),-8,IF(V12>0,-V12*'Cover & Assumptions'!$F$54,0)) -> -34.02
B15: Lifecycle R&D ($mm, ~5% of revenue) | C15: =-C12*0.05 -> 0 | D15: =-D12*0.05 -> 0 | E15: =-E12*0.05 -> 0 | F15: =-F12*0.05 -> 0 | G15: =-G12*0.05 -> 0 | H15: =-H12*0.05 -> 0 | I15: =-I12*0.05 -> -8.1 | J15: =-J12*0.05 -> -16.2 | ... V15: =-V12*0.05 -> -6.075
B16: Pre-launch Phase 3 program cost ($mm) | C16: =IF(AND(C9<0,C9>=-3),-40,0) -> 0 | D16: =IF(AND(D9<0,D9>=-3),-40,0) -> 0 | E16: =IF(AND(E9<0,E9>=-3),-40,0) -> -40 | F16: =IF(AND(F9<0,F9>=-3),-40,0) -> -40 | G16: =IF(AND(G9<0,G9>=-3),-40,0) -> -40 | H16: =IF(AND(H9<0,H9>=-3),-40,0) -> 0 | I16: =IF(AND(I9<0,I9>=-3),-40,0) -> 0 | J16: =IF(AND(J9<0,J9>=-3),-40,0) -> 0 | ... V16: =IF(AND(V9<0,V9>=-3),-40,0) -> 0
B17: Unrisked pre-tax cash flow ($mm) | C17: =C12+C13+C14+C15+C16 -> 0 | D17: =D12+D13+D14+D15+D16 -> 0 | E17: =E12+E13+E14+E15+E16 -> -40 | F17: =F12+F13+F14+F15+F16 -> -48 | G17: =G12+G13+G14+G15+G16 -> -48 | H17: =H12+H13+H14+H15+H16 -> 0 | I17: =I12+I13+I14+I15+I16 -> 84.24 | J17: =J12+J13+J14+J15+J16 -> 168.48 | ... V17: =V12+V13+V14+V15+V16 -> 63.18
B18: Effective cash tax rate | C18: 0 | D18: 0 | E18: 0 | F18: 0 | G18: 0 | H18: 0 | I18: 0 | J18: 0 | K18: 0.21 | L18: 0.21 | M18: 0.21 | N18: 0.21 | O18: 0.21 | P18: 0.21 | Q18: 0.21 | R18: 0.21 | S18: 0.21 | T18: 0.21 | U18: 0.21 | V18: 0.21 | X18: ESTIMATE — assumes NOLs shelter income through 2033, then statutory 21% federal rate. We do not have CNTB's actual NOL balance/carryforward schedule (10-K tax footnote) — verify.
B19: Unrisked after-tax cash flow ($mm) | C19: =IF(C17>0,C17*(1-C18),C17) -> 0 | D19: =IF(D17>0,D17*(1-D18),D17) -> 0 | E19: =IF(E17>0,E17*(1-E18),E17) -> -40 | F19: =IF(F17>0,F17*(1-F18),F17) -> -48 | G19: =IF(G17>0,G17*(1-G18),G17) -> -48 | H19: =IF(H17>0,H17*(1-H18),H17) -> 0 | I19: =IF(I17>0,I17*(1-I18),I17) -> 84.24 | J19: =IF(J17>0,J17*(1-J18),J17) -> 168.48 | ... V19: =IF(V17>0,V17*(1-V18),V17) -> 49.9122
B20: Cumulative PoS to approval — Asthma | C20: ='Cover & Assumptions'!$F$42*'Cover & Assumptions'!$F$43 -> 0.3
B21: Risk-adjusted after-tax cash flow ($mm) | C21: =C19*$C$20 -> 0 | D21: =D19*$C$20 -> 0 | E21: =E19*$C$20 -> -12 | F21: =F19*$C$20 -> -14.4 | G21: =G19*$C$20 -> -14.4 | H21: =H19*$C$20 -> 0 | I21: =I19*$C$20 -> 25.272 | J21: =J19*$C$20 -> 50.544 | ... V21: =V19*$C$20 -> 14.97366
B22: Discount factor | C22: =1/(1+'Cover & Assumptions'!$F$55)^(C$5-2026+0.5) -> 0.94280904 | D22: =1/(1+'Cover & Assumptions'!$F$55)^(D$5-2026+0.5) -> 0.83805248 | E22: =1/(1+'Cover & Assumptions'!$F$55)^(E$5-2026+0.5) -> 0.74493554 | F22: =1/(1+'Cover & Assumptions'!$F$55)^(F$5-2026+0.5) -> 0.66216492 | G22: =1/(1+'Cover & Assumptions'!$F$55)^(G$5-2026+0.5) -> 0.58859104 | H22: =1/(1+'Cover & Assumptions'!$F$55)^(H$5-2026+0.5) -> 0.52319204 | I22: =1/(1+'Cover & Assumptions'!$F$55)^(I$5-2026+0.5) -> 0.46505959 | J22: =1/(1+'Cover & Assumptions'!$F$55)^(J$5-2026+0.5) -> 0.4133863 | ... V22: =1/(1+'Cover & Assumptions'!$F$55)^(V$5-2026+0.5) -> 0.10058328
B23: PV of risk-adjusted cash flow ($mm) | C23: =C21*C22 -> 0 | D23: =D21*D22 -> 0 | E23: =E21*E22 -> -8.9392265 | F23: =F21*F22 -> -9.5351749 | G23: =G21*G22 -> -8.475711 | H23: =H21*H22 -> 0 | I23: =I21*I22 -> 11.752986 | J23: =J21*J22 -> 20.894197 | ... V23: =V21*V22 -> 1.5060999
B25: rNPV — Asthma program ($mm) | C25: =SUM(C23:V23) -> 164.16708
A27: PROGRAM 2 — ACUTE EXACERBATIONS OF COPD (US)
B29: Years since launch | C29: =C$5-'Cover & Assumptions'!$F$50 -> -6 | D29: =D$5-'Cover & Assumptions'!$F$50 -> -5 | E29: =E$5-'Cover & Assumptions'!$F$50 -> -4 | F29: =F$5-'Cover & Assumptions'!$F$50 -> -3 | G29: =G$5-'Cover & Assumptions'!$F$50 -> -2 | H29: =H$5-'Cover & Assumptions'!$F$50 -> -1 | I29: =I$5-'Cover & Assumptions'!$F$50 -> 0 | J29: =J$5-'Cover & Assumptions'!$F$50 -> 1 | ... V29: =V$5-'Cover & Assumptions'!$F$50 -> 13
B30: Penetration of eligible population | C30: =IF(C29<0,0,IF(C29>='Cover & Assumptions'!$F$52-'Cover & Assumptions'!$F$50,'Cover & Assumptions'!$F$48*0.15*0.8,MIN('Cover & Assumptions'!$F$48*0.8,'Cover & Assumptions'!$F$48*0.8*C29/'Cover & Assumptions'!$F$51))) -> 0 | D30: =IF(D29<0,0,IF(D29>='Cover & Assumptions'!$F$52-'Cover & Assumptions'!$F$50,'Cover & Assumptions'!$F$48*0.15*0.8,MIN('Cover & Assumptions'!$F$48*0.8,'Cover & Assumptions'!$F$48*0.8*D29/'Cover & Assumptions'!$F$51))) -> 0 | E30: =IF(E29<0,0,IF(E29>='Cover & Assumptions'!$F$52-'Cover & Assumptions'!$F$50,'Cover & Assumptions'!$F$48*0.15*0.8,MIN('Cover & Assumptions'!$F$48*0.8,'Cover & Assumptions'!$F$48*0.8*E29/'Cover & Assumptions'!$F$51))) -> 0 | F30: =IF(F29<0,0,IF(F29>='Cover & Assumptions'!$F$52-'Cover & Assumptions'!$F$50,'Cover & Assumptions'!$F$48*0.15*0.8,MIN('Cover & Assumptions'!$F$48*0.8,'Cover & Assumptions'!$F$48*0.8*F29/'Cover & Assumptions'!$F$51))) -> 0 | G30: =IF(G29<0,0,IF(G29>='Cover & Assumptions'!$F$52-'Cover & Assumptions'!$F$50,'Cover & Assumptions'!$F$48*0.15*0.8,MIN('Cover & Assumptions'!$F$48*0.8,'Cover & Assumptions'!$F$48*0.8*G29/'Cover & Assumptions'!$F$51))) -> 0 | H30: =IF(H29<0,0,IF(H29>='Cover & Assumptions'!$F$52-'Cover & Assumptions'!$F$50,'Cover & Assumptions'!$F$48*0.15*0.8,MIN('Cover & Assumptions'!$F$48*0.8,'Cover & Assumptions'!$F$48*0.8*H29/'Cover & Assumptions'!$F$51))) -> 0 | I30: =IF(I29<0,0,IF(I29>='Cover & Assumptions'!$F$52-'Cover & Assumptions'!$F$50,'Cover & Assumptions'!$F$48*0.15*0.8,MIN('Cover & Assumptions'!$F$48*0.8,'Cover & Assumptions'!$F$48*0.8*I29/'Cover & Assumptions'!$F$51))) -> 0 | J30: =IF(J29<0,0,IF(J29>='Cover & Assumptions'!$F$52-'Cover & Assumptions'!$F$50,'Cover & Assumptions'!$F$48*0.15*0.8,MIN('Cover & Assumptions'!$F$48*0.8,'Cover & Assumptions'!$F$48*0.8*J29/'Cover & Assumptions'!$F$51))) -> 0.032 | ... V30: =IF(V29<0,0,IF(V29>='Cover & Assumptions'!$F$52-'Cover & Assumptions'!$F$50,'Cover & Assumptions'!$F$48*0.15*0.8,MIN('Cover & Assumptions'!$F$48*0.8,'Cover & Assumptions'!$F$48*0.8*V29/'Cover & Assumptions'!$F$51))) -> 0.024 | X30: COPD peak penetration set at 80% of the Asthma assumption, reflecting a more crowded/skeptical prescriber base for a first-in-class acute-exacerbation biologic in COPD specifically.
B31: Treated patients (000s) | C31: ='Cover & Assumptions'!$F$46*C30 -> 0 | D31: ='Cover & Assumptions'!$F$46*D30 -> 0 | E31: ='Cover & Assumptions'!$F$46*E30 -> 0 | F31: ='Cover & Assumptions'!$F$46*F30 -> 0 | G31: ='Cover & Assumptions'!$F$46*G30 -> 0 | H31: ='Cover & Assumptions'!$F$46*H30 -> 0 | I31: ='Cover & Assumptions'!$F$46*I30 -> 0 | J31: ='Cover & Assumptions'!$F$46*J30 -> 17.6 | ... V31: ='Cover & Assumptions'!$F$46*V30 -> 13.2
B32: Unrisked US net revenue ($mm) | C32: =C31*1000*'Cover & Assumptions'!$F$47/1000000 -> 0 | D32: =D31*1000*'Cover & Assumptions'!$F$47/1000000 -> 0 | E32: =E31*1000*'Cover & Assumptions'!$F$47/1000000 -> 0 | F32: =F31*1000*'Cover & Assumptions'!$F$47/1000000 -> 0 | G32: =G31*1000*'Cover & Assumptions'!$F$47/1000000 -> 0 | H32: =H31*1000*'Cover & Assumptions'!$F$47/1000000 -> 0 | I32: =I31*1000*'Cover & Assumptions'!$F$47/1000000 -> 0 | J32: =J31*1000*'Cover & Assumptions'!$F$47/1000000 -> 158.4 | ... V32: =V31*1000*'Cover & Assumptions'!$F$47/1000000 -> 118.8
B33: COGS ($mm) | C33: =-C32*'Cover & Assumptions'!$F$53 -> 0 | D33: =-D32*'Cover & Assumptions'!$F$53 -> 0 | E33: =-E32*'Cover & Assumptions'!$F$53 -> 0 | F33: =-F32*'Cover & Assumptions'!$F$53 -> 0 | G33: =-G32*'Cover & Assumptions'!$F$53 -> 0 | H33: =-H32*'Cover & Assumptions'!$F$53 -> 0 | I33: =-I32*'Cover & Assumptions'!$F$53 -> 0 | J33: =-J32*'Cover & Assumptions'!$F$53 -> -23.76 | ... V33: =-V32*'Cover & Assumptions'!$F$53 -> -17.82
B34: SG&A ($mm, incremental — shared field force w/ Asthma) | C34: =IF(AND(C29<0,C29>=-2),-4,IF(C32>0,-C32*'Cover & Assumptions'!$F$54*0.7,0)) -> 0 | D34: =IF(AND(D29<0,D29>=-2),-4,IF(D32>0,-D32*'Cover & Assumptions'!$F$54*0.7,0)) -> 0 | E34: =IF(AND(E29<0,E29>=-2),-4,IF(E32>0,-E32*'Cover & Assumptions'!$F$54*0.7,0)) -> 0 | F34: =IF(AND(F29<0,F29>=-2),-4,IF(F32>0,-F32*'Cover & Assumptions'!$F$54*0.7,0)) -> 0 | G34: =IF(AND(G29<0,G29>=-2),-4,IF(G32>0,-G32*'Cover & Assumptions'!$F$54*0.7,0)) -> -4 | H34: =IF(AND(H29<0,H29>=-2),-4,IF(H32>0,-H32*'Cover & Assumptions'!$F$54*0.7,0)) -> -4 | I34: =IF(AND(I29<0,I29>=-2),-4,IF(I32>0,-I32*'Cover & Assumptions'!$F$54*0.7,0)) -> 0 | J34: =IF(AND(J29<0,J29>=-2),-4,IF(J32>0,-J32*'Cover & Assumptions'!$F$54*0.7,0)) -> -31.0464 | ... V34: =IF(AND(V29<0,V29>=-2),-4,IF(V32>0,-V32*'Cover & Assumptions'!$F$54*0.7,0)) -> -23.2848 | X34: Incremental SG&A only, at 70% of the standalone rate — COPD launches into an already-built acute-care commercial infrastructure from the Asthma launch.
B35: Lifecycle R&D ($mm, ~5% of revenue) | C35: =-C32*0.05 -> 0 | D35: =-D32*0.05 -> 0 | E35: =-E32*0.05 -> 0 | F35: =-F32*0.05 -> 0 | G35: =-G32*0.05 -> 0 | H35: =-H32*0.05 -> 0 | I35: =-I32*0.05 -> 0 | J35: =-J32*0.05 -> -7.92 | ... V35: =-V32*0.05 -> -5.94
B36: Pre-launch Phase 3 program cost ($mm) | C36: =IF(AND(C29<0,C29>=-3),-35,0) -> 0 | D36: =IF(AND(D29<0,D29>=-3),-35,0) -> 0 | E36: =IF(AND(E29<0,E29>=-3),-35,0) -> 0 | F36: =IF(AND(F29<0,F29>=-3),-35,0) -> -35 | G36: =IF(AND(G29<0,G29>=-3),-35,0) -> -35 | H36: =IF(AND(H29<0,H29>=-3),-35,0) -> -35 | I36: =IF(AND(I29<0,I29>=-3),-35,0) -> 0 | J36: =IF(AND(J29<0,J29>=-3),-35,0) -> 0 | ... V36: =IF(AND(V29<0,V29>=-3),-35,0) -> 0
B37: Unrisked pre-tax cash flow ($mm) | C37: =C32+C33+C34+C35+C36 -> 0 | D37: =D32+D33+D34+D35+D36 -> 0 | E37: =E32+E33+E34+E35+E36 -> 0 | F37: =F32+F33+F34+F35+F36 -> -35 | G37: =G32+G33+G34+G35+G36 -> -39 | H37: =H32+H33+H34+H35+H36 -> -39 | I37: =I32+I33+I34+I35+I36 -> 0 | J37: =J32+J33+J34+J35+J36 -> 95.6736 | ... V37: =V32+V33+V34+V35+V36 -> 71.7552
B38: Effective cash tax rate | C38: 0 | D38: 0 | E38: 0 | F38: 0 | G38: 0 | H38: 0 | I38: 0 | J38: 0 | K38: 0 | L38: 0.21 | M38: 0.21 | N38: 0.21 | O38: 0.21 | P38: 0.21 | Q38: 0.21 | R38: 0.21 | S38: 0.21 | T38: 0.21 | U38: 0.21 | V38: 0.21
B39: Unrisked after-tax cash flow ($mm) | C39: =IF(C37>0,C37*(1-C38),C37) -> 0 | D39: =IF(D37>0,D37*(1-D38),D37) -> 0 | E39: =IF(E37>0,E37*(1-E38),E37) -> 0 | F39: =IF(F37>0,F37*(1-F38),F37) -> -35 | G39: =IF(G37>0,G37*(1-G38),G37) -> -39 | H39: =IF(H37>0,H37*(1-H38),H37) -> -39 | I39: =IF(I37>0,I37*(1-I38),I37) -> 0 | J39: =IF(J37>0,J37*(1-J38),J37) -> 95.6736 | ... V39: =IF(V37>0,V37*(1-V38),V37) -> 56.686608
B40: Cumulative PoS to approval — COPD | C40: ='Cover & Assumptions'!$F$44 -> 0.28
B41: Risk-adjusted after-tax cash flow ($mm) | C41: =C39*$C$40 -> 0 | D41: =D39*$C$40 -> 0 | E41: =E39*$C$40 -> 0 | F41: =F39*$C$40 -> -9.8 | G41: =G39*$C$40 -> -10.92 | H41: =H39*$C$40 -> -10.92 | I41: =I39*$C$40 -> 0 | J41: =J39*$C$40 -> 26.788608 | ... V41: =V39*$C$40 -> 15.87225
B42: Discount factor | C42: =1/(1+'Cover & Assumptions'!$F$55)^(C$5-2026+0.5) -> 0.94280904 | D42: =1/(1+'Cover & Assumptions'!$F$55)^(D$5-2026+0.5) -> 0.83805248 | E42: =1/(1+'Cover & Assumptions'!$F$55)^(E$5-2026+0.5) -> 0.74493554 | F42: =1/(1+'Cover & Assumptions'!$F$55)^(F$5-2026+0.5) -> 0.66216492 | G42: =1/(1+'Cover & Assumptions'!$F$55)^(G$5-2026+0.5) -> 0.58859104 | H42: =1/(1+'Cover & Assumptions'!$F$55)^(H$5-2026+0.5) -> 0.52319204 | I42: =1/(1+'Cover & Assumptions'!$F$55)^(I$5-2026+0.5) -> 0.46505959 | J42: =1/(1+'Cover & Assumptions'!$F$55)^(J$5-2026+0.5) -> 0.4133863 | ... V42: =1/(1+'Cover & Assumptions'!$F$55)^(V$5-2026+0.5) -> 0.10058328
B43: PV of risk-adjusted cash flow ($mm) | C43: =C41*C42 -> 0 | D43: =D41*D42 -> 0 | E43: =E41*E42 -> 0 | F43: =F41*F42 -> -6.4892163 | G43: =G41*G42 -> -6.4274142 | H43: =H41*H42 -> -5.7132571 | I43: =I41*I42 -> 0 | J43: =J41*J42 -> 11.074044 | ... V43: =V41*V42 -> 1.5964831
B45: rNPV — COPD program ($mm) | C45: =SUM(C43:V43) -> 143.7253
A47: rNPV SUMMARY & PER-SHARE VALUE
B49: rNPV — Asthma program ($mm) | C49: =C25 -> 164.16708
B50: rNPV — COPD program ($mm) | C50: =C45 -> 143.7253
...

Sheet DCF Model
B2: DCF Model — Unrisked "If It Succeeds" Ceiling Case
B3: THIS IS THE CEILING CASE, NOT THE BASE CASE. It assumes both Phase 2 programs succeed and convert to approval with certainty (100% PoS) — it strips out the binary clinical/regulatory risk-adjustment that the rNPV tab applies, but keeps the same underlying operating engine (same patient counts, pricing, cost structure, launch timing selected on the Cover tab). Use it to see what CNTB is worth if the science works, not as a probability-weighted target.
B7: Fiscal Year | C7: ='rNPV Model'!C5 -> 2026 | D7: ='rNPV Model'!D5 -> 2027 | E7: ='rNPV Model'!E5 -> 2028 | F7: ='rNPV Model'!F5 -> 2029 | G7: ='rNPV Model'!G5 -> 2030 | H7: ='rNPV Model'!H5 -> 2031 | I7: ='rNPV Model'!I5 -> 2032 | J7: ='rNPV Model'!J5 -> 2033 | ... V7: ='rNPV Model'!V5 -> 2045
A9: UNRISKED OPERATING CASH FLOW (linked from rNPV Model tab — same engine, no PoS haircut)
B11: Unrisked after-tax cash flow — Asthma ($mm) | C11: ='rNPV Model'!C19 -> 0 | D11: ='rNPV Model'!D19 -> 0 | E11: ='rNPV Model'!E19 -> -40 | F11: ='rNPV Model'!F19 -> -48 | G11: ='rNPV Model'!G19 -> -48 | H11: ='rNPV Model'!H19 -> 0 | I11: ='rNPV Model'!I19 -> 84.24 | J11: ='rNPV Model'!J19 -> 168.48 | ... V11: ='rNPV Model'!V19 -> 49.9122
B12: Unrisked after-tax cash flow — COPD ($mm) | C12: ='rNPV Model'!C39 -> 0 | D12: ='rNPV Model'!D39 -> 0 | E12: ='rNPV Model'!E39 -> 0 | F12: ='rNPV Model'!F39 -> -35 | G12: ='rNPV Model'!G39 -> -39 | H12: ='rNPV Model'!H39 -> -39 | I12: ='rNPV Model'!I39 -> 0 | J12: ='rNPV Model'!J39 -> 95.6736 | ... V12: ='rNPV Model'!V39 -> 56.686608
B13: Total unrisked after-tax cash flow ($mm) | C13: =C11+C12 -> 0 | D13: =D11+D12 -> 0 | E13: =E11+E12 -> -40 | F13: =F11+F12 -> -83 | G13: =G11+G12 -> -87 | H13: =H11+H12 -> -39 | I13: =I11+I12 -> 84.24 | J13: =J11+J12 -> 264.1536 | ... V13: =V11+V12 -> 106.59881
B14: Discount factor (mid-year convention, @ selected WACC) | C14: =1/(1+'Cover & Assumptions'!$F$55)^(C7-2026+0.5) -> 0.94280904 | D14: =1/(1+'Cover & Assumptions'!$F$55)^(D7-2026+0.5) -> 0.83805248 | E14: =1/(1+'Cover & Assumptions'!$F$55)^(E7-2026+0.5) -> 0.74493554 | F14: =1/(1+'Cover & Assumptions'!$F$55)^(F7-2026+0.5) -> 0.66216492 | G14: =1/(1+'Cover & Assumptions'!$F$55)^(G7-2026+0.5) -> 0.58859104 | H14: =1/(1+'Cover & Assumptions'!$F$55)^(H7-2026+0.5) -> 0.52319204 | I14: =1/(1+'Cover & Assumptions'!$F$55)^(I7-2026+0.5) -> 0.46505959 | J14: =1/(1+'Cover & Assumptions'!$F$55)^(J7-2026+0.5) -> 0.4133863 | ... V14: =1/(1+'Cover & Assumptions'!$F$55)^(V7-2026+0.5) -> 0.10058328
B15: PV of unrisked cash flow ($mm) | C15: =C13*C14 -> 0 | D15: =D13*D14 -> 0 | E15: =E13*E14 -> -29.797422 | F15: =F13*F14 -> -54.959689 | G15: =G13*G14 -> -51.207421 | H15: =H13*H14 -> -20.404489 | I15: =I13*I14 -> 39.17662 | J15: =J13*J14 -> 109.19748 | ... V15: =V13*V14 -> 10.722058
B17: Sum of PV, explicit period 2026-2045 ($mm) | C17: =SUM(C15:V15) -> 1060.5282
A19: TERMINAL VALUE
B21: Terminal-year (2045) post-LOE steady-state cash flow ($mm) | C21: =V13 -> 106.59881 | X21: By 2045 both programs are well past the modeled loss-of-exclusivity year in every scenario, so this is already a genericized/eroded residual (~15% of peak), not peak-year cash flow — using peak-year cash flow here would materially overstate the terminal value.
B22: Terminal growth rate | C22: 0 | X22: Set to 0% — a mature, off-patent/biosimilar-eroded revenue stream should not be assumed to grow in perpetuity. This is a conservative but standard convention.
B23: Terminal value, undiscounted ($mm) | C23: =C21*(1+C22)/('Cover & Assumptions'!$F$55-C22) -> 852.79046
B24: PV of terminal value ($mm) | C24: =C23*V14 -> 85.776466
A26: DCF SUMMARY & PER-SHARE VALUE (CEILING CASE)
B28: Sum of PV, explicit period ($mm) | C28: =C17 -> 1060.5282
B29: PV of terminal value ($mm) | C29: =C24 -> 85.776466
B30: China milestones, unrisked, discounted @ 50% PV credit ($mm) | C30: =110*0.5 -> 55 | X30: Ceiling-case treatment: assumes half of the $110mm remaining Simcere milestones land, discounted for timing but not for Simcere-execution risk (which the rNPV tab already prices in separately).
B31: China royalty stream, unrisked NPV ($mm) | C31: ='Cover & Assumptions'!$F$57*2 -> 60 | X31: Ceiling case: 2x the risk-adjusted China royalty NPV used in the rNPV tab, as a simple proxy for removing most (not all) of the discount applied there.
B32: Enterprise value, DCF ceiling case ($mm) | C32: =SUM(C28:C31) -> 1261.3047
B33: Plus: net cash ($mm) | C33: ='Cover & Assumptions'!C15-'Cover & Assumptions'!C16 -> 52.031
B34: Total equity value, DCF ceiling case ($mm) | C34: =C32+C33 -> 1313.3357
B35: Fully-diluted shares (mm) | C35: ='Cover & Assumptions'!C12 -> 78.48
B37: DCF value per share — CEILING CASE ($) | C37: =C34/C35 -> 16.734655
B39: This ceiling case is the upside scenario a bull would cite if SEABREEZE data are clean and rademikibart becomes the first biologic approved for acute asthma/COPD exacerbations. It is not risk-adjusted for the still-open Phase 2 binary event in September/Q4 2026, and should never be quoted as a price target on its own — pair it with the rNPV tab's Low/Base/High.

Sheet Relative Valuation
B2: Relative Valuation — EV / Risk-Adjusted Peak Sales
B3: Genuine peer set for a single-asset, Phase 2, respiratory/T2-inflammation biotech is thin — most direct comps have either been acquired or are far more advanced. We use one active public peer (Upstream Bio) for a market-derived multiple, and two precedent transactions as sanity checks, not as the primary multiple source.
A5: PEER SCREEN & INCLUSION/EXCLUSION LOGIC
B7: Upstream Bio (UPB) | C7: INCLUDED — primary multiple source | E7: Single-asset (verekitug, TSLP-receptor antagonist), Phase 2/3, severe asthma + CRSwNP + COPD. Directly comparable stage/business model: pre-revenue, single-mechanism, T2-respiratory biologic, similarly exposed to one binary readout at a time (UPB fell ~47% on its own Phase 2 VALIANT asthma miss in Feb 2026 — a useful real-world illustration of CNTB's own Sept-2026 risk).
B8: Aiolos Bio / GSK | C8: REFERENCE ONLY — precedent transaction, not a multiple | E8: GSK acquired Aiolos (Phase 2-ready TSLP mAb, asthma-only, Jan-2024) for $1.0bn upfront + up to $400mm in milestones. This is a control/M&A price, not a market-trading multiple, and covers a single indication (asthma) vs. CNTB's two (asthma+COPD) — used below only as a directional sanity check, not blended into the multiple.
B9: Apogee Therapeutics / AbbVie | C9: EXCLUDED from multiple | E9: AbbVie's ~$10.9bn acquisition (2026) is real and topical, but Apogee is a multi-asset platform (zumilokibart in AD/asthma/EoE + APG222 + more) with an $800mm synthetic-royalty and $500mm debt facility already in place and cash into 2029 — a materially larger, more advanced, more de-risked company. Applying its scale of multiple to a single Phase-2 asset like CNTB would be a scale artifact, not a valid read-across. Mentioned only as evidence that large pharma has active, recent appetite for the IL-4/IL-13/T2 respiratory space.
A11: PEER 1 — UPSTREAM BIO (UPB): MULTIPLE DERIVATION
B13: UPB enterprise value ($mm) | C13: 190 | E13: Seeking Alpha initiation (30-May-2026) cites UPB trading at 'an enterprise value under $200M' following the post-VALIANT-data selloff; we use $190mm as a point estimate. VERIFY against a current 10-Q cash balance and market cap before relying on this.
B14: UPB risk-adjusted peak WW sales estimate ($mm, 2035) | C14: 2700 | E14: Mizuho equity research (17-Dec-2025): '$2.7 billion in risk-adjusted worldwide sales by 2035' for verekitug across asthma + CRSwNP + COPD combined. This is already probability-weighted, not an unrisked peak-sales figure — important for how we apply the resulting multiple below.
B15: Implied EV / risk-adjusted peak sales multiple | C15: =C13/C14 -> 0.07037037 | E15: Note the basis: this multiple is EV per dollar of RISK-ADJUSTED (already probability-weighted) peak sales — not unrisked peak sales. We must apply it to CNTB's risk-adjusted peak sales figure below, not the unrisked one, or we would be double- or under-counting clinical risk (a 'share-count artifact' -style error in the other direction).
A17: CNTB — RISK-ADJUSTED PEAK SALES (SAME BASIS AS THE PEER MULTIPLE)
B19: Peak unrisked US net revenue — Asthma ($mm) | C19: =MAX('rNPV Model'!C12:V12) -> 810
B20: Peak unrisked US net revenue — COPD ($mm) | C20: =MAX('rNPV Model'!C32:V32) -> 792
B21: Combined PoS to approval — Asthma | C21: ='rNPV Model'!$C$20 -> 0.3
B22: Combined PoS to approval — COPD | C22: ='rNPV Model'!$C$40 -> 0.28
B23: CNTB risk-adjusted peak sales ($mm) | C23: =C19*C21+C20*C22 -> 464.76
A25: IMPLIED VALUE — EV / PEAK-SALES METHOD
B27: Implied CNTB enterprise value ($mm) | C27: =C15*C23 -> 32.705333
B28: Plus: net cash ($mm) | C28: ='Cover & Assumptions'!C15-'Cover & Assumptions'!C16 -> 52.031
B29: Implied CNTB equity value ($mm) | C29: =C27+C28 -> 84.736333
B30: Fully-diluted shares (mm) | C30: ='Cover & Assumptions'!C12 -> 78.48
B32: Relative valuation — value per share ($) | C32: =C29/C30 -> 1.0797188
A34: PRECEDENT TRANSACTION SANITY CHECKS (not used in the multiple above)
B36: Aiolos Bio / GSK, Jan-2024 | C36: $1.0bn upfront + up to $400mm milestones ($1.4bn total) | E36: Phase 2-ready, single TSLP mAb, asthma only (+ CRSwNP option). If CNTB's dual-indication (asthma+COPD), Phase-2-de-risked-by-Sept-2026 rademikibart commanded even a similar per-indication control price, that alone implies a value well above CNTB's current ~$150mm market cap — a rough upper-bound sanity check on the downside case, not a target.
B37: Apogee Therapeutics / AbbVie, 2026 | C37: $10.9bn all-cash | E37: Confirms continued large-pharma appetite for the IL-4/IL-13/T2 space, but Apogee is a multi-program, more clinically advanced platform — not scalable down to a single-asset Phase 2 comp.
B39: Caution on this whole tab: with one true public peer, the 'multiple' above is a single data point, not a statistically robust market multiple — treat it as directionally informative, weight it accordingly in the blend on the Price Target Summary tab, and revisit the moment a second respiratory Phase 2 peer trades publicly or a transaction closes at a disclosed price.

Sheet Price Target Summary
B2: Price Target Summary
B3: Blends the risk-adjusted (rNPV) and relative-valuation methods with editable weights. The DCF ceiling case is shown for reference, not blended in — including an unrisked 'if it succeeds' number in a probability-weighted target would double-count upside.
B5: Current share price ($) | C5: ='Cover & Assumptions'!C10 -> 2.4
A7: METHOD BLEND (Base case scenario)
B9: Method | C9: Value / share ($) | D9: Weight | E9: Weighted contribution
B10: rNPV — bottom-up, risk-adjusted (Base) | C10: ='rNPV Model'!C59 -> 5.0732252 | D10: 0.6 | E10: =C10*D10 -> 3.0439351
B11: Relative valuation — EV / risk-adj. peak sales | C11: ='Relative Valuation'!C32 -> 1.0797188 | D11: 0.4 | E11: =C11*D11 -> 0.43188753
B12: Weight check (should = 100%) | D12: =D10+D11 -> 1
B13: BLENDED PRICE TARGET (Base case, ~12mo) | E13: =E10+E11 -> 3.4758226
B14: Implied upside / (downside) vs. current price | E14: =E13/C5-1 -> 0.44825944
B16: For reference, not blended:
B17: DCF ceiling case ("if it succeeds") | C17: ='DCF Model'!C37 -> 16.734655
B18: rNPV — Low scenario | C18: ='rNPV Model'!C59 -> 5.0732252 | F18: NOTE: this cell reads the Selected-scenario rNPV output, which only reflects Low when the Cover tab's scenario selector is set to Low. It will not update independently — flip the selector to see it live.
B19: Street consensus target (per sell-side, Jul-2026) | C19: 7 | F19: Median of 7 analysts per StockAnalysis.com (Jul-2026): Wainwright $7 (Buy), BTIG $10 (Buy), Piper Sandler $7 (Overweight), Oppenheimer $8 (Outperform), Canaccord $6 (Buy), Cantor Fitzgerald $4 (Overweight). See Sell-Side Reconciliation section of the memo.
A21: SENSITIVITY — WHAT MOVES THE NUMBER MOST (one input flexed at a time, rNPV Base case, $/share impact)
B23: Driver | C23: Downside flex | D23: Upside flex | E23: Notes
B24: Net price per treated patient (±25%) | C24: -1.13 | D24: 1.13 | E24: Largest single lever — and the one we have the least real data on. First pricing signal will likely come from post-approval payer commentary, years away; near-term, watch for any investor-day pricing hints.
B25: Peak penetration of eligible population (±5pp) | C25: -1.13 | D25: 1.13 | E25: Tied with price for largest impact — reflects both efficacy differentiation and how fast ED/urgent-care physicians adopt a biologic at point of acute care.
B26: WACC / discount rate (±2pp) | C26: -0.75 | D26: 0.94 | E26: Meaningful given the long dated (2030-32+) launch — a re-rating of biotech risk premia broadly would move this without any CNTB-specific news.
B27: PoS: COPD approval (±10pp) | C27: -0.65 | D27: 0.65 | E27: COPD is intentionally the higher-risk, higher-uncertainty program in this file (see Assumptions tab notes) — a COPD-specific miss or hold would show up here first.
B28: PoS: Asthma Phase 2 positive readout (±10pp) | C28: -0.35 | D28: 0.35 | E28: Smaller than it may look ONLY because it's partially offset by the Ph2→approval conversion probability multiplying it down regardless; the September 2026 readout itself is still the single highest-stakes near-term event — a negative readout removes the Asthma program (~$164mm of Base-case rNPV) almost entirely, not just this incremental slice.
B30: Read this as: holding everything else at Base, flexing ONE input by the stated amount moves rNPV/share by the amount shown (recomputed after the Q1'26 10-Q correction to fully-diluted shares and cash). Because the drivers interact (the Low/High columns on the Cover tab move several at once), the full Low-to-High spread on the rNPV tab is much wider than the sum of these one-at-a-time moves - that gap is itself the honest message: this stock's value is dominated by compounding uncertainty, not any single number.
