Workbook

Sheet Cover & Assumptions
A1: SPRUCE BIOSCIENCES, INC. (NASDAQ: SPRB)
A2: rNPV / DCF / Relative Valuation Model — Prepared for internal research use — Not investment advice
A3: Analyst working file. Build date: 18-Jul-2026. Ticker data sourced from SEC filings, company press releases, and public market data (see Sources tab).
A5: COMPANY SNAPSHOT
A6: Ticker / Exchange | B6: SPRB / Nasdaq Capital Market
A7: Sector | B7: Biopharmaceuticals — Rare / Ultra-Orphan Disease
A8: Lead Asset | B8: Tralesinidase Alfa (TA-ERT) — enzyme replacement therapy for MPS IIIB (Sanfilippo Syndrome Type B)
A9: Secondary Asset | B9: SPR202 (CAH, licensed from HMNC Holding, up to $390mm in potential milestones) -- unmodeled optionality. NOTE: the tildacerfont/HMNC TAMARIND Phase 2 trial for Major Depressive Disorder was DISCONTINUED in Q1 2026 after a serious adverse event (significant liver enzyme elevation) -- this program is no longer a source of optionality value.
A10: Regulatory Status | B10: FDA Breakthrough Therapy Designation (TA-ERT, Oct 2025); BLA submission planned 4Q26; HS-biomarker accepted as basis for accelerated approval
A11: Stock price (last, source date) | B11: 43.54 | C11: Updated from user-provided TradingView chart (SPRB, 1D), captured mid-Jul-2026: last=$43.54. Supersedes the earlier $52.51 (3-Jul-26) source figure — stock has since pulled back. HIGHLY VOLATILE, re-check before use.
A12: Basic shares outstanding (est., pro forma post Apr-26 offering) | B12: 2752278 | C12: Reconciled 18-Jul-2026: user-provided Godel Terminal data shows Shares Out 2.8M / Market Cap $119.83M at $43.54, which implies 2,752,182 shares -- a near-exact match (<100 shares) to this figure (1,372,278 confirmed 3/31/26 + ~1,380,000 est. from the Apr-2026 $69.0mm offering). This CONFIRMS the offering added common shares (or as-converted equivalents) to the actual outstanding count. A user-supplied TradingView fundamentals chart had appeared to show the reported count still flat at 1.372M post-offering, which led to an incorrect revision in a prior pass of this model -- the likely explanation is that TradingView's quarterly fundamentals series plots balance-sheet-date share counts (i.e., still shows the 31-Mar-26 figure) rather than a real-time count, so it simply hadn't caught up. Reverted to this estimate, cross-checked against Godel.
A13: Market capitalization (est.) | B13: =B11*B12 -> 1.1983418e+08
A14: Cash & equivalents (pro forma, 30-Apr-26, preliminary) | B14: 107300000 | C14: Company preliminary unaudited estimate disclosed in Q1-26 earnings release (13-May-2026); $54.1mm at 3/31/26 + ~$65mm net proceeds from $69.0mm gross Apr-26 offering, less fees.
A15: Guided cash runway | B15: Into 2H 2027 (past anticipated FDA approval / launch readiness)
A16: Note: 1-for-75 reverse stock split effective 4-Aug-2025 | B16: All share/price figures below are POST-SPLIT unless noted.
A18: MASTER ASSUMPTIONS (edit yellow cells — flow to rNPV, DCF & Price Target tabs)
A19: Assumption | B19: Low | C19: Base | D19: High | E19: Unit | G19: Notes / Source
A20: Valuation date | B20: 01/07/2026 | C20: 01/07/2026 | D20: 01/07/2026 | G20: Mid-2026 val. date used for discounting.
A21: WACC / discount rate (DCF & rNPV) | B21: 0.12 | C21: 0.15 | D21: 0.18 | G21: Micro-cap, single-asset, pre-revenue biotech — high cost of capital vs. large-cap biotech (~8-10%).
A22: Overall probability of commercial success (rNPV risk-adjustment) | B22: 0.6 | C22: 0.78 | D22: 0.9 | G22: Reflects BLA-ready status, Breakthrough Therapy Designation, and FDA alignment on HS biomarker as accelerated-approval endpoint — de-risked vs. typical Phase 3 asset, but commercial/reimbursement execution risk remains.
A23: US incidence — MPS IIIB (1 in N live births) | B23: 300000 | C23: 200000 | D23: 150000 | E23: 1 in N | G23: Company materials cite ~1:200,000; published epidemiology ranges 1:70,000 (all MPS III) with IIIB a minority subtype — wide uncertainty. VALIDATE WITH KOLs.
A24: US live births / year | B24: 3600000 | C24: 3600000 | D24: 3600000 | G24: CDC/NCHS approx. steady-state.
A25: EU5 incidence — MPS IIIB (1 in N live births) | B25: 250000 | C25: 160000 | D25: 110000 | E25: 1 in N | G25: IIIB historically over-represented in Southern/Western Europe (Portugal, Greece, Netherlands) vs. IIIA in Northern Europe — assumption, not company guidance.
A26: EU5 live births / year | B26: 1500000 | C26: 1500000 | D26: 1500000 | G26: Approx. DE/FR/IT/ES/UK aggregate.
A27: Diagnosed prevalent pool at launch (US+EU5, backlog) | B27: 120 | C27: 220 | D27: 340 | G27: Ultra-rare, under-diagnosed disease; backlog of already-identified patients awaiting a therapy. Pure estimate — flagged as a data gap.
A28: Peak addressable-patient capture rate (of diagnosed pool) | B28: 0.55 | C28: 0.7 | D28: 0.85 | G28: Ultra-rare CNS disease, no approved alternative, breakthrough designation supports high uptake once launched.
A29: Annual price per patient (US, list) | B29: 400000 | C29: 500000 | D29: 600000 | G29: Benchmarked to CNS/ICV-delivered ERT comps (Brineura $400-500k) from Spruce's own investor deck; TA-ERT admin (Ommaya reservoir) is more complex than IM/IV ERTs, supporting premium pricing.
A30: Ex-US net price as % of US price | B30: 0.55 | C30: 0.65 | D30: 0.75 | G30: Typical US/ex-US rare-disease price differential.
A31: Annual price escalation | B31: 0.01 | C31: 0.02 | D31: 0.03 | G31: Modest annual list price growth, typical for rare disease ERTs.
A32: COGS as % of net sales | B32: 0.25 | C32: 0.18 | D32: 0.12 | G32: Biologic manufactured via mammalian cell culture + ICV delivery device/kit costs; assumed to improve with scale.
A33: BioMarin royalty on worldwide net sales | B33: 0.13 | C33: 0.1 | D33: 0.08 | G33: Per license: 'high-single-digit to low-teens' royalty to BioMarin (worldwide exclusive license for TA-ERT). Base case = 10%.
A34: BioMarin regulatory/dev. milestone (paid at BLA approval) | B34: 22500000 | C34: 22500000 | D34: 22500000 | G34: Disclosed cap per license terms (of up to $122.5mm total; $22.5mm is dev/reg tranche).
A35: BioMarin sales milestones (cumulative, paid as thresholds hit) | B35: 100000000 | C35: 100000000 | D35: 100000000 | G35: Disclosed cap per license terms; modeled as triggered on cumulative net sales thresholds (see rNPV tab).
A36: SG&A at steady state (% of net sales) | B36: 0.45 | C36: 0.35 | D36: 0.28 | G36: Small commercial team (~10 people per investor deck) targeting an ultra-niche prescriber base; leverages as revenue scales.
A37: Pre-launch R&D + G&A run-rate (annual, 2026-2027) | B37: 58000000 | C37: 48000000 | D37: 40000000 | G37: Q1-26 opex annualized (~$48mm) with commercial build-out into launch; Low case = higher spend / slower efficiency.
A38: Tax rate (long-run, if profitable) | B38: 0.25 | C38: 0.21 | D38: 0.18 | G38: US federal + state blended; NOLs shelter early profits (not separately modeled — conservative).
A39: IP / regulatory exclusivity horizon | B39: 2037 | C39: 2037 | D39: 2037 | E39: year | G39: Per company materials: 'IP Exclusivity to 2037'.
A40: Priority Review Voucher (PRV) monetization value, if awarded | B40: 20000000 | C40: 40000000 | D40: 100000000 | G40: Contingent on reauthorization of the Rare Pediatric Disease PRV program + FDA approval. Recent PRV sales have ranged ~$30-150mm. NOT included in base rNPV/DCF — shown as an optionality add-on only.
A42: SCENARIO SELECTOR
A43: Active scenario for rNPV / DCF tabs (1=Low/Bear, 2=Base, 3=High/Bull) | B43: 2 | C43: Change this single cell to 1, 2, or 3 to flip every downstream tab between Bear / Base / Bull cases.
...

Sheet Balance Sheet & Runway
A1: BALANCE SHEET, CAPITAL STRUCTURE & CASH RUNWAY
A3: BALANCE SHEET SNAPSHOT (as reported, $ actuals)
B4: 31-Dec-2024 | C4: 31-Dec-2025 | D4: 31-Mar-2026 | E4: 30-Apr-2026 (prelim.)
A5: Cash & cash equivalents | B5: 38753000 | C5: 48900000 | D5: 54100000 | E5: 107300000 | G5: 10-K/10-Q & Q1-26 press release (13-May-26); 30-Apr-26 figure is the company's preliminary unaudited pro forma estimate post-offering, not GAAP-filed.
A6: Total assets | D6: 56200000 | G6: Q1-26 10-Q.
A7: Total liabilities | D7: 21500000 | G7: Q1-26 10-Q; includes Avenue Capital term loan + lease + accrued liabilities.
A8: Total stockholders' equity | D8: 34600000 | G8: Q1-26 10-Q.
A10: DEBT SCHEDULE — AVENUE CAPITAL TERM LOAN (Jan-2026)
A11: Facility size (up to) | B11: 50000000 | G11: Signed January 2026; tranched drawdowns tied to time/milestone conditions (Tranche 2/3).
A12: Maturity | B12: 01-Jul-2029 | G12: Per 10-Q disclosure of the 'Avenue Maturity Date'.
A13: Illustrative all-in interest cost | B13: 0.11 | G13: Estimate for a secured venture-debt facility to a sub-scale biotech; exact coupon not itemized in filings reviewed.
A14: Prepayment fee (Year 1) | B14: 0.03 | G14: 3.0% of outstanding principal if prepaid within 12 months of closing; steps down thereafter.
A15: Financial covenants | B15: None disclosed (no minimum cash covenant per 10-Q) | G15: Reduces near-term restructuring/covenant-breach risk vs. typical venture debt.
A17: RECENT FINANCING ACTIVITY (dilution / capital raised)
A18: Date | B18: Instrument | C18: Gross proceeds | D18: Terms
A19: Jul-2025 | B19: Reverse stock split (1-for-75) | D19: 42.2mm shares -> ~0.6mm shares; regained Nasdaq bid-price compliance.
A20: Jan-2026 | B20: Avenue Capital term loan | C20: 50000000 | D20: Tranched venture debt; no min. cash covenant disclosed.
A21: Nov-2025 | B21: S-3 shelf registration effective | D21: Standing shelf capacity for further ATM/offerings.
A22: Apr-2026 | B22: Underwritten public offering (common + pre-funded warrants) | C22: 69000000 | D22: Priced ~$50/sh; closed April 2026; extended runway from 4Q26 guidance into 2H27 guidance.
A24: CASH RUNWAY BUILD (opex-only check, excludes launch revenue — see rNPV tab for full P&L)
B25: 2026E | C25: 2027E | D25: 2028E | E25: Notes
A26: Beginning cash (pro forma, incl. Apr-26 raise) | B26: ='Balance Sheet & Runway'!$E$5 -> 107300000
A27: (-) Operating cash burn (R&D + G&A, pre-commercial) | B27: =-'Cover & Assumptions'!$C$37 -> -48000000 | C27: =-'Cover & Assumptions'!$C$37*1.15 -> -55200000 | D27: =-'Cover & Assumptions'!$C$37*0.6 -> -28800000 | E27: 2027E assumes higher spend for commercial launch build-out (+15%); 2028E assumes commercial revenue is by then materially offsetting cash opex (see rNPV tab) — shown lower here to avoid double counting.
A28: (-) Debt service (interest on Avenue facility, illustrative) | B28: =-'Balance Sheet & Runway'!$B$11*'Balance Sheet & Runway'!$B$13 -> -5500000 | C28: =-'Balance Sheet & Runway'!$B$11*'Balance Sheet & Runway'!$B$13 -> -5500000 | D28: =-'Balance Sheet & Runway'!$B$11*'Balance Sheet & Runway'!$B$13 -> -5500000 | E28: Interest-only approximation; principal amortization begins after the interest-only period per Avenue Loan Agreement (not separately scheduled).
A29: (-) BioMarin regulatory milestone (paid at BLA approval) | B29: =0 -> 0 | C29: =-'Cover & Assumptions'!$C$34 -> -22500000 | D29: =0 -> 0 | E29: Assumes BLA approval / associated $22.5mm milestone to BioMarin lands in 2027.
A30: Ending cash (before further financing) | B30: =B26+B27+B28+B29 -> 53800000 | C30: =B30+C27+C28+C29 -> -29400000 | D30: =C30+D27+D28+D29 -> -63700000
A32: Runway conclusion: on these assumptions (no further capital raised, opex-only, no launch revenue credited), modeled cash lasts into 2027 — broadly consistent with management's stated guidance of runway into 2H 2027, since that guidance implicitly assumes early launch revenue and/or further ATM draws start contributing before cash is exhausted. Treat this as a conservative floor, not a base case forecast. The company retains standing shelf capacity (Nov-2025 S-3) and is very likely to raise additional capital around the BLA submission/approval window regardless of clinical outcome — further dilution should be expected.
A34: SHARE COUNT & DILUTION (post 1-for-75 reverse split, all figures in shares)
A35: Common shares outstanding, 31-Mar-2026 | B35: 1372278 | D35: Q1-26 10-Q cover page.
A36: Est. new shares issued, Apr-2026 offering ($69.0mm gross @ ~$50/sh) | B36: 1380000 | D36: Reconciled 18-Jul-2026 against user-supplied Godel Terminal data (Shares Out 2.8M, Mkt Cap $119.83M @ $43.54 -> implies 2,752,182 shares, matching 1,372,278 + this line almost exactly). This confirms the Apr-2026 offering did add to the actual outstanding share count. Still an estimate pending the Q2-26 10-Q, but now cross-validated by a second independent data source.
A37: Est. basic shares outstanding, pro forma | B37: =B35+B36 -> 2752278
A38: Equity awards (options + RSUs) outstanding, est. | B38: 150000 | D38: Scaled from Dec-2024 disclosure (5.8mm pre-split -> ~77k post-split) plus 2025-26 inducement/annual grants seen in Form 4 filings. Confirm exact count.
A39: Warrants outstanding, est. | B39: 60000 | D39: Feb-2023 private-placement warrants (12.7mm pre-split -> ~169k post-split), likely partly exercised/expired since. Confirm exact count -- wide uncertainty flagged. (Apr-2026 offering shares are now counted in the basic share line above, not here -- see reconciliation note there.)
A40: Fully-diluted shares outstanding, est. | B40: =B37+B38+B39 -> 2962278

Sheet rNPV Model
A1: rNPV MODEL — RISK-ADJUSTED NET PRESENT VALUE (Absolute Valuation)
A2: All figures in USD unless noted. Blue = input / linked assumption. Explicit forecast 2026-2040 (through IP exclusivity horizon of 2037 + 3-year post-cliff decline). Active scenario driven by the selector on the Cover & Assumptions tab.
A4: EPIDEMIOLOGY & PATIENT FORECAST — TA-ERT / MPS IIIB (US + EU5)
A5: Scenario in use (1=Low, 2=Base, 3=High) | C5: ='Cover & Assumptions'!$B$43 -> 2
A6: US new incident patients / year | C6: ='Cover & Assumptions'!$C$24/INDEX('Cover & Assumptions'!$B$23:$D$23,'Cover & Assumptions'!$B$43) -> 18
A7: EU5 new incident patients / year | C7: ='Cover & Assumptions'!$C$26/INDEX('Cover & Assumptions'!$B$25:$D$25,'Cover & Assumptions'!$B$43) -> 9.375
A8: Diagnosed prevalent pool at launch (US+EU5) | C8: =INDEX('Cover & Assumptions'!$B$27:$D$27,'Cover & Assumptions'!$B$43) -> 220
A9: Total addressable pool by peak (prevalent + ~5yrs new incidence) | C9: =C8+(C6+C7)*5 -> 356.875
A10: Peak capture rate (% of addressable pool on therapy) | C10: =INDEX('Cover & Assumptions'!$B$28:$D$28,'Cover & Assumptions'!$B$43) -> 0.7
A11: Peak treated patients (steady state) | C11: =C9*C10 -> 249.8125
C13: 2026 | D13: 2027 | E13: 2028 | F13: 2029 | G13: 2030 | H13: 2031 | I13: 2032 | J13: 2033 | K13: 2034 | L13: 2035 | M13: 2036 | N13: 2037 | O13: 2038 | P13: 2039 | Q13: 2040
A14: Key milestone / phase | C14: BLA filed 4Q | D14: Approval + launch | N14: Exclusivity ends
A15: % of peak patients on therapy (ramp / decline curve) | C15: 0 | D15: 0.15 | E15: 0.38 | F15: 0.58 | G15: 0.76 | H15: 0.9 | I15: 0.97 | J15: 1 | K15: 1 | L15: 1 | M15: 1 | N15: 0.85 | O15: 0.72 | P15: 0.65 | Q15: 0.6
A16: Active treated patients | C16: =ROUND($C$11*C15,0) -> 0 | D16: =ROUND($C$11*D15,0) -> 37 | E16: =ROUND($C$11*E15,0) -> 95 | F16: =ROUND($C$11*F15,0) -> 145 | G16: =ROUND($C$11*G15,0) -> 190 | H16: =ROUND($C$11*H15,0) -> 225 | I16: =ROUND($C$11*I15,0) -> 242 | J16: =ROUND($C$11*J15,0) -> 250 | ... Q16: =ROUND($C$11*Q15,0) -> 150
A18: REVENUE BUILD
A19: Blended net price per patient / year | C19: =(INDEX('Cover & Assumptions'!$B$29:$D$29,'Cover & Assumptions'!$B$43)*0.55+INDEX('Cover & Assumptions'!$B$29:$D$29,'Cover & Assumptions'!$B$43)*INDEX('Cover & Assumptions'!$B$30:$D$30,'Cover & Assumptions'!$B$43)*0.45) -> 421250 | D19: =C19*(1+INDEX('Cover & Assumptions'!$B$31:$D$31,'Cover & Assumptions'!$B$43)) -> 429675 | E19: =D19*(1+INDEX('Cover & Assumptions'!$B$31:$D$31,'Cover & Assumptions'!$B$43)) -> 438268.5 | F19: =E19*(1+INDEX('Cover & Assumptions'!$B$31:$D$31,'Cover & Assumptions'!$B$43)) -> 447033.87 | G19: =F19*(1+INDEX('Cover & Assumptions'!$B$31:$D$31,'Cover & Assumptions'!$B$43)) -> 455974.55 | H19: =G19*(1+INDEX('Cover & Assumptions'!$B$31:$D$31,'Cover & Assumptions'!$B$43)) -> 465094.04 | I19: =H19*(1+INDEX('Cover & Assumptions'!$B$31:$D$31,'Cover & Assumptions'!$B$43)) -> 474395.92 | J19: =I19*(1+INDEX('Cover & Assumptions'!$B$31:$D$31,'Cover & Assumptions'!$B$43)) -> 483883.84 | K19: =J19*(1+INDEX('Cover & Assumptions'!$B$31:$D$31,'Cover & Assumptions'!$B$43)) -> 493561.51 | ... Q19: =P19*(1+INDEX('Cover & Assumptions'!$B$31:$D$31,'Cover & Assumptions'!$B$43)) -> 555830.43
A20: Gross-to-net product revenue | C20: =C16*C19 -> 0 | D20: =D16*D19 -> 15897975 | E20: =E16*E19 -> 41635508 | F20: =F16*F19 -> 64819911 | G20: =G16*G19 -> 86635164 | H20: =H16*H19 -> 1.0464616e+08 | I20: =I16*I19 -> 1.1480381e+08 | J20: =J16*J19 -> 1.2097096e+08 | ... Q20: =Q16*Q19 -> 83374564
A22: OPERATING MODEL (unrisked — pre probability-of-success adjustment)
A23: COGS | C23: =-C20*INDEX('Cover & Assumptions'!$B$32:$D$32,'Cover & Assumptions'!$B$43) -> 0 | D23: =-D20*INDEX('Cover & Assumptions'!$B$32:$D$32,'Cover & Assumptions'!$B$43) -> -2861635.5 | E23: =-E20*INDEX('Cover & Assumptions'!$B$32:$D$32,'Cover & Assumptions'!$B$43) -> -7494391.3 | F23: =-F20*INDEX('Cover & Assumptions'!$B$32:$D$32,'Cover & Assumptions'!$B$43) -> -11667584 | G23: =-G20*INDEX('Cover & Assumptions'!$B$32:$D$32,'Cover & Assumptions'!$B$43) -> -15594330 | H23: =-H20*INDEX('Cover & Assumptions'!$B$32:$D$32,'Cover & Assumptions'!$B$43) -> -18836309 | I23: =-I20*INDEX('Cover & Assumptions'!$B$32:$D$32,'Cover & Assumptions'!$B$43) -> -20664686 | J23: =-J20*INDEX('Cover & Assumptions'!$B$32:$D$32,'Cover & Assumptions'!$B$43) -> -21774773 | ... Q23: =-Q20*INDEX('Cover & Assumptions'!$B$32:$D$32,'Cover & Assumptions'!$B$43) -> -15007422
A24: Gross profit | C24: =C20+C23 -> 0 | D24: =D20+D23 -> 13036340 | E24: =E20+E23 -> 34141116 | F24: =F20+F23 -> 53152327 | G24: =G20+G23 -> 71040834 | H24: =H20+H23 -> 85809850 | I24: =I20+I23 -> 94139126 | J24: =J20+J23 -> 99196187 | ... Q24: =Q20+Q23 -> 68367143
A25: BioMarin royalty on net sales | C25: =-C20*INDEX('Cover & Assumptions'!$B$33:$D$33,'Cover & Assumptions'!$B$43) -> 0 | D25: =-D20*INDEX('Cover & Assumptions'!$B$33:$D$33,'Cover & Assumptions'!$B$43) -> -1589797.5 | E25: =-E20*INDEX('Cover & Assumptions'!$B$33:$D$33,'Cover & Assumptions'!$B$43) -> -4163550.8 | F25: =-F20*INDEX('Cover & Assumptions'!$B$33:$D$33,'Cover & Assumptions'!$B$43) -> -6481991.1 | G25: =-G20*INDEX('Cover & Assumptions'!$B$33:$D$33,'Cover & Assumptions'!$B$43) -> -8663516.4 | H25: =-H20*INDEX('Cover & Assumptions'!$B$33:$D$33,'Cover & Assumptions'!$B$43) -> -10464616 | I25: =-I20*INDEX('Cover & Assumptions'!$B$33:$D$33,'Cover & Assumptions'!$B$43) -> -11480381 | J25: =-J20*INDEX('Cover & Assumptions'!$B$33:$D$33,'Cover & Assumptions'!$B$43) -> -12097096 | ... Q25: =-Q20*INDEX('Cover & Assumptions'!$B$33:$D$33,'Cover & Assumptions'!$B$43) -> -8337456.4
A26: BioMarin regulatory/dev. milestone | C26: =0 -> 0 | D26: =-'Cover & Assumptions'!$C$34 -> -22500000 | E26: =0 -> 0 | F26: =0 -> 0 | G26: =0 -> 0 | H26: =0 -> 0 | I26: =0 -> 0 | J26: =0 -> 0 | K26: =0 -> 0 | L26: =0 -> 0 | ... Q26: =0 -> 0
A27: BioMarin sales milestones (cumulative net sales triggers @ $75mm / $200mm) | C27: =-IF(AND((C20)>=75000000,(0)<75000000),'Cover & Assumptions'!$C$35*0.5,0)-IF(AND((C20)>=200000000,(0)<200000000),'Cover & Assumptions'!$C$35*0.5,0) -> 0 | D27: =-IF(AND((C20+D20)>=75000000,(C20)<75000000),'Cover & Assumptions'!$C$35*0.5,0)-IF(AND((C20+D20)>=200000000,(C20)<200000000),'Cover & Assumptions'!$C$35*0.5,0) -> 0 | E27: =-IF(AND((C20+D20+E20)>=75000000,(C20+D20)<75000000),'Cover & Assumptions'!$C$35*0.5,0)-IF(AND((C20+D20+E20)>=200000000,(C20+D20)<200000000),'Cover & Assumptions'!$C$35*0.5,0) -> 0 | F27: =-IF(AND((C20+D20+E20+F20)>=75000000,(C20+D20+E20)<75000000),'Cover & Assumptions'!$C$35*0.5,0)-IF(AND((C20+D20+E20+F20)>=200000000,(C20+D20+E20)<200000000),'Cover & Assumptions'!$C$35*0.5,0) -> -50000000 | G27: =-IF(AND((C20+D20+E20+F20+G20)>=75000000,(C20+D20+E20+F20)<75000000),'Cover & Assumptions'!$C$35*0.5,0)-IF(AND((C20+D20+E20+F20+G20)>=200000000,(C20+D20+E20+F20)<200000000),'Cover & Assumptions'!$C$35*0.5,0) -> -50000000 | H27: =-IF(AND((C20+D20+E20+F20+G20+H20)>=75000000,(C20+D20+E20+F20+G20)<75000000),'Cover & Assumptions'!$C$35*0.5,0)-IF(AND((C20+D20+E20+F20+G20+H20)>=200000000,(C20+D20+E20+F20+G20)<200000000),'Cover & Assumptions'!$C$35*0.5,0) -> 0 | I27: =-IF(AND((C20+D20+E20+F20+G20+H20+I20)>=75000000,(C20+D20+E20+F20+G20+H20)<75000000),'Cover & Assumptions'!$C$35*0.5,0)-IF(AND((C20+D20+E20+F20+G20+H20+I20)>=200000000,(C20+D20+E20+F20+G20+H20)<200000000),'Cover & Assumptions'!$C$35*0.5,0) -> 0 | J27: =-IF(AND((C20+D20+E20+F20+G20+H20+I20+J20)>=75000000,(C20+D20+E20+F20+G20+H20+I20)<75000000),'Cover & Assumptions'!$C$35*0.5,0)-IF(AND((C20+D20+E20+F20+G20+H20+I20+J20)>=200000000,(C20+D20+E20+F20+G20+H20+I20)<200000000),'Cover & Assumptions'!$C$35*0.5,0) -> 0 | K27: =-IF(AND((C20+D20+E20+F20+G20+H20+I20+J20+K20)>=75000000,(C20+D20+E20+F20+G20+H20+I20+J20)<75000000),'Cover & Assumptions'!$C$35*0.5,0)-IF(AND((C20+D20+E20+F20+G20+H20+I20+J20+K20)>=200000000,(C20+D20+E20+F20+G20+H20+I20+J20)<200000000),'Cover & Assumptions'!$C$35*0.5,0) -> 0 | L27: =-IF(AND((C20+D20+E20+F20+G20+H20+I20+J20+K20+L20)>=75000000,(C20+D20+E20+F20+G20+H20+I20+J20+K20)<75000000),'Cover & Assumptions'!$C$35*0.5,0)-IF(AND((C20+D20+E20+F20+G20+H20+I20+J20+K20+L20)>=200000000,(C20+D20+E20+F20+G20+H20+I20+J20+K20)<200000000),'Cover & Assumptions'!$C$35*0.5,0) -> 0 | M27: =-IF(AND((C20+D20+E20+F20+G20+H20+I20+J20+K20+L20+M20)>=75000000,(C20+D20+E20+F20+G20+H20+I20+J20+K20+L20)<75000000),'Cover & Assumptions'!$C$35*0.5,0)-IF(AND((C20+D20+E20+F20+G20+H20+I20+J20+K20+L20+M20)>=200000000,(C20+D20+E20+F20+G20+H20+I20+J20+K20+L20)<200000000),'Cover & Assumptions'!$C$35*0.5,0) -> 0 | N27: =-IF(AND((C20+D20+E20+F20+G20+H20+I20+J20+K20+L20+M20+N20)>=75000000,(C20+D20+E20+F20+G20+H20+I20+J20+K20+L20+M20)<75000000),'Cover & Assumptions'!$C$35*0.5,0)-IF(AND((C20+D20+E20+F20+G20+H20+I20+J20+K20+L20+M20+N20)>=200000000,(C20+D20+E20+F20+G20+H20+I20+J20+K20+L20+M20)<200000000),'Cover & Assumptions'!$C$35*0.5,0) -> 0 | O27: =-IF(AND((C20+D20+E20+F20+G20+H20+I20+J20+K20+L20+M20+N20+O20)>=75000000,(C20+D20+E20+F20+G20+H20+I20+J20+K20+L20+M20+N20)<75000000),'Cover & Assumptions'!$C$35*0.5,0)-IF(AND((C20+D20+E20+F20+G20+H20+I20+J20+K20+L20+M20+N20+O20)>=200000000,(C20+D20+E20+F20+G20+H20+I20+J20+K20+L20+M20+N20)<200000000),'Cover & Assumptions'!$C$35*0.5,0) -> 0 | P27: =-IF(AND((C20+D20+E20+F20+G20+H20+I20+J20+K20+L20+M20+N20+O20+P20)>=75000000,(C20+D20+E20+F20+G20+H20+I20+J20+K20+L20+M20+N20+O20)<75000000),'Cover & Assumptions'!$C$35*0.5,0)-IF(AND((C20+D20+E20+F20+G20+H20+I20+J20+K20+L20+M20+N20+O20+P20)>=200000000,(C20+D20+E20+F20+G20+H20+I20+J20+K20+L20+M20+N20+O20)<200000000),'Cover & Assumptions'!$C$35*0.5,0) -> 0 | Q27: =-IF(AND((C20+D20+E20+F20+G20+H20+I20+J20+K20+L20+M20+N20+O20+P20+Q20)>=75000000,(C20+D20+E20+F20+G20+H20+I20+J20+K20+L20+M20+N20+O20+P20)<75000000),'Cover & Assumptions'!$C$35*0.5,0)-IF(AND((C20+D20+E20+F20+G20+H20+I20+J20+K20+L20+M20+N20+O20+P20+Q20)>=200000000,(C20+D20+E20+F20+G20+H20+I20+J20+K20+L20+M20+N20+O20+P20)<200000000),'Cover & Assumptions'!$C$35*0.5,0) -> 0
A28: SG&A | C28: =0 -> 0 | D28: =-MAX(D20*INDEX('Cover & Assumptions'!$B$36:$D$36,'Cover & Assumptions'!$B$43),8000000) -> -8000000 | E28: =-MAX(E20*INDEX('Cover & Assumptions'!$B$36:$D$36,'Cover & Assumptions'!$B$43),8000000) -> -14572428 | F28: =-MAX(F20*INDEX('Cover & Assumptions'!$B$36:$D$36,'Cover & Assumptions'!$B$43),8000000) -> -22686969 | G28: =-MAX(G20*INDEX('Cover & Assumptions'!$B$36:$D$36,'Cover & Assumptions'!$B$43),8000000) -> -30322307 | H28: =-MAX(H20*INDEX('Cover & Assumptions'!$B$36:$D$36,'Cover & Assumptions'!$B$43),8000000) -> -36626156 | I28: =-MAX(I20*INDEX('Cover & Assumptions'!$B$36:$D$36,'Cover & Assumptions'!$B$43),8000000) -> -40181334 | J28: =-MAX(J20*INDEX('Cover & Assumptions'!$B$36:$D$36,'Cover & Assumptions'!$B$43),8000000) -> -42339836 | K28: =-MAX(K20*INDEX('Cover & Assumptions'!$B$36:$D$36,'Cover & Assumptions'!$B$43),8000000) -> -43186632 | ... Q28: =-MAX(Q20*INDEX('Cover & Assumptions'!$B$36:$D$36,'Cover & Assumptions'!$B$43),8000000) -> -29181098
A29: Pre-launch R&D + corporate G&A (2026 only, in this model) | C29: =-'Cover & Assumptions'!$C$37 -> -48000000 | D29: =0 -> 0 | E29: =0 -> 0 | F29: =0 -> 0 | G29: =0 -> 0 | H29: =0 -> 0 | I29: =0 -> 0 | J29: =0 -> 0 | K29: =0 -> 0 | ... Q29: =0 -> 0
A30: EBIT (unrisked) | C30: =SUM(C24+C25+C26+C27+C28+C29) -> -48000000 | D30: =SUM(D24+D25+D26+D27+D28+D29) -> -19053458 | E30: =SUM(E24+E25+E26+E27+E28+E29) -> 15405138 | F30: =SUM(F24+F25+F26+F27+F28+F29) -> -26016633 | G30: =SUM(G24+G25+G26+G27+G28+G29) -> -17944989 | H30: =SUM(H24+H25+H26+H27+H28+H29) -> 38719079 | I30: =SUM(I24+I25+I26+I27+I28+I29) -> 42477411 | J30: =SUM(J24+J25+J26+J27+J28+J29) -> 44759255 | ... Q30: =SUM(Q24+Q25+Q26+Q27+Q28+Q29) -> 30848589
A31: Cash taxes (only when EBIT>0, simplified — NOLs not modeled) | C31: =-MAX(C30,0)*INDEX('Cover & Assumptions'!$B$38:$D$38,'Cover & Assumptions'!$B$43) -> 0 | D31: =-MAX(D30,0)*INDEX('Cover & Assumptions'!$B$38:$D$38,'Cover & Assumptions'!$B$43) -> 0 | E31: =-MAX(E30,0)*INDEX('Cover & Assumptions'!$B$38:$D$38,'Cover & Assumptions'!$B$43) -> -3235078.9 | F31: =-MAX(F30,0)*INDEX('Cover & Assumptions'!$B$38:$D$38,'Cover & Assumptions'!$B$43) -> 0 | G31: =-MAX(G30,0)*INDEX('Cover & Assumptions'!$B$38:$D$38,'Cover & Assumptions'!$B$43) -> 0 | H31: =-MAX(H30,0)*INDEX('Cover & Assumptions'!$B$38:$D$38,'Cover & Assumptions'!$B$43) -> -8131006.5 | I31: =-MAX(I30,0)*INDEX('Cover & Assumptions'!$B$38:$D$38,'Cover & Assumptions'!$B$43) -> -8920256.2 | J31: =-MAX(J30,0)*INDEX('Cover & Assumptions'!$B$38:$D$38,'Cover & Assumptions'!$B$43) -> -9399443.5 | ... Q31: =-MAX(Q30,0)*INDEX('Cover & Assumptions'!$B$38:$D$38,'Cover & Assumptions'!$B$43) -> -6478203.6
A32: Unrisked unlevered free cash flow | C32: =C30+C31 -> -48000000 | D32: =D30+D31 -> -19053458 | E32: =E30+E31 -> 12170059 | F32: =F30+F31 -> -26016633 | G32: =G30+G31 -> -17944989 | H32: =H30+H31 -> 30588072 | I32: =I30+I31 -> 33557154 | J32: =J30+J31 -> 35359811 | ... Q32: =Q30+Q31 -> 24370385
A34: RISK ADJUSTMENT & DISCOUNTING
A35: Probability of commercial success applied (post-launch flows only) | C35: =1 -> 1 | D35: =INDEX('Cover & Assumptions'!$B$22:$D$22,'Cover & Assumptions'!$B$43) -> 0.78 | E35: =INDEX('Cover & Assumptions'!$B$22:$D$22,'Cover & Assumptions'!$B$43) -> 0.78 | F35: =INDEX('Cover & Assumptions'!$B$22:$D$22,'Cover & Assumptions'!$B$43) -> 0.78 | G35: =INDEX('Cover & Assumptions'!$B$22:$D$22,'Cover & Assumptions'!$B$43) -> 0.78 | H35: =INDEX('Cover & Assumptions'!$B$22:$D$22,'Cover & Assumptions'!$B$43) -> 0.78 | I35: =INDEX('Cover & Assumptions'!$B$22:$D$22,'Cover & Assumptions'!$B$43) -> 0.78 | J35: =INDEX('Cover & Assumptions'!$B$22:$D$22,'Cover & Assumptions'!$B$43) -> 0.78 | K35: =INDEX('Cover & Assumptions'!$B$22:$D$22,'Cover & Assumptions'!$B$43) -> 0.78 | ... Q35: =INDEX('Cover & Assumptions'!$B$22:$D$22,'Cover & Assumptions'!$B$43) -> 0.78
A36: Pre-launch (2026) R&D/G&A spend is treated as a certain, already-committed cost (100% weight) since it is incurred whether or not the program ultimately succeeds; all 2027+ cash flows (revenue-dependent) are multiplied by the single overall probability of commercial success set on the Cover tab.
A37: Risk-adjusted (rNPV) cash flow | C37: =C32*C35 -> -48000000 | D37: =D32*D35 -> -14861697 | E37: =E32*E35 -> 9492645.9 | F37: =F32*F35 -> -20292974 | G37: =G32*G35 -> -13997092 | H37: =H32*H35 -> 23858696 | I37: =I32*I35 -> 26174580 | J37: =J32*J35 -> 27580653 | ... Q37: =Q32*Q35 -> 19008900
A38: Discount period (years from valuation date) | C38: =(DATE(2026,7,1)-'Cover & Assumptions'!$C$20)/365 -> 0.47945205 | D38: =(DATE(2027,7,1)-'Cover & Assumptions'!$C$20)/365 -> 1.4794521 | E38: =(DATE(2028,7,1)-'Cover & Assumptions'!$C$20)/365 -> 2.4821918 | F38: =(DATE(2029,7,1)-'Cover & Assumptions'!$C$20)/365 -> 3.4821918 | G38: =(DATE(2030,7,1)-'Cover & Assumptions'!$C$20)/365 -> 4.4821918 | H38: =(DATE(2031,7,1)-'Cover & Assumptions'!$C$20)/365 -> 5.4821918 | I38: =(DATE(2032,7,1)-'Cover & Assumptions'!$C$20)/365 -> 6.4849315 | J38: =(DATE(2033,7,1)-'Cover & Assumptions'!$C$20)/365 -> 7.4849315 | K38: =(DATE(2034,7,1)-'Cover & Assumptions'!$C$20)/365 -> 8.4849315 | L38: =(DATE(2035,7,1)-'Cover & Assumptions'!$C$20)/365 -> 9.4849315 | M38: =(DATE(2036,7,1)-'Cover & Assumptions'!$C$20)/365 -> 10.487671 | N38: =(DATE(2037,7,1)-'Cover & Assumptions'!$C$20)/365 -> 11.487671 | O38: =(DATE(2038,7,1)-'Cover & Assumptions'!$C$20)/365 -> 12.487671 | P38: =(DATE(2039,7,1)-'Cover & Assumptions'!$C$20)/365 -> 13.487671 | Q38: =(DATE(2040,7,1)-'Cover & Assumptions'!$C$20)/365 -> 14.490411
A39: Discount factor @ WACC | C39: =1/(1+INDEX('Cover & Assumptions'!$B$21:$D$21,'Cover & Assumptions'!$B$43))^C38 -> 0.93518664 | D39: =1/(1+INDEX('Cover & Assumptions'!$B$21:$D$21,'Cover & Assumptions'!$B$43))^D38 -> 0.81320578 | E39: =1/(1+INDEX('Cover & Assumptions'!$B$21:$D$21,'Cover & Assumptions'!$B$43))^E38 -> 0.70686474 | F39: =1/(1+INDEX('Cover & Assumptions'!$B$21:$D$21,'Cover & Assumptions'!$B$43))^F38 -> 0.61466499 | G39: =1/(1+INDEX('Cover & Assumptions'!$B$21:$D$21,'Cover & Assumptions'!$B$43))^G38 -> 0.5344913 | H39: =1/(1+INDEX('Cover & Assumptions'!$B$21:$D$21,'Cover & Assumptions'!$B$43))^H38 -> 0.46477504 | I39: =1/(1+INDEX('Cover & Assumptions'!$B$21:$D$21,'Cover & Assumptions'!$B$43))^I38 -> 0.40399749 | J39: =1/(1+INDEX('Cover & Assumptions'!$B$21:$D$21,'Cover & Assumptions'!$B$43))^J38 -> 0.35130216 | ... Q39: =1/(1+INDEX('Cover & Assumptions'!$B$21:$D$21,'Cover & Assumptions'!$B$43))^Q38 -> 0.13196639
A40: PV of risk-adjusted cash flow | C40: =C37*C39 -> -44888959 | D40: =D37*D39 -> -12085618 | E40: =E37*E39 -> 6710016.7 | F40: =F37*F39 -> -12473380 | G40: =G37*G39 -> -7481323.7 | H40: =H37*H39 -> 11088927 | I40: =I37*I39 -> 10574465 | J40: =J37*J39 -> 9689143 | ... Q40: =Q37*Q39 -> 2508536
A42: rNPV SUMMARY & IMPLIED PRICE TARGET
A43: Sum of PV, risk-adjusted operating cash flows (2026-2040) | C43: =SUM(C40:Q40) -> -1417200
A44: PRV monetization optionality (risk-adjusted, undiscounted add-on) | C44: ='Cover & Assumptions'!$C$40*INDEX('Cover & Assumptions'!$B$22:$D$22,'Cover & Assumptions'!$B$43)*0.5 -> 15600000 | D44: Haircut further by 50% for PRV-program reauthorization risk, on top of the commercial-success probability already applied. Shown separately — excluded from the headline rNPV below to keep the core case conservative.
A45: Enterprise rNPV (core operating case, excl. PRV optionality) | C45: =C43 -> -1417200
A46: (+) Cash & equivalents (pro forma, 30-Apr-26) | C46: ='Balance Sheet & Runway'!$E$5 -> 107300000
...

Sheet DCF Model
A1: DCF MODEL — INTRINSIC VALUE IF TA-ERT SUCCEEDS (Unrisked Operating Case + Terminal Value)
A2: This tab pulls the identical revenue/cost engine from the rNPV tab but does NOT apply the probability-of-commercial-success haircut — it answers 'what is SPRB worth if TA-ERT is approved and launches as modeled?' It is the natural complement to the rNPV tab (which already answers 'what is it worth today, risk-adjusted?'). Compare the two: the gap between them is the value the market is being asked to underwrite on regulatory/commercial execution risk. A terminal value beyond 2040 captures a moderate post-exclusivity decline (biologics face slower biosimilar erosion than small molecules; no biosimilar TA-ERT competitor currently in development).
A4: UNRISKED FREE CASH FLOW (linked from rNPV tab operating build)
C5: 2026 | D5: 2027 | E5: 2028 | F5: 2029 | G5: 2030 | H5: 2031 | I5: 2032 | J5: 2033 | K5: 2034 | L5: 2035 | M5: 2036 | N5: 2037 | O5: 2038 | P5: 2039 | Q5: 2040
A6: Revenue | C6: ='rNPV Model'!C20 -> 0 | D6: ='rNPV Model'!D20 -> 15897975 | E6: ='rNPV Model'!E20 -> 41635508 | F6: ='rNPV Model'!F20 -> 64819911 | G6: ='rNPV Model'!G20 -> 86635164 | H6: ='rNPV Model'!H20 -> 1.0464616e+08 | I6: ='rNPV Model'!I20 -> 1.1480381e+08 | J6: ='rNPV Model'!J20 -> 1.2097096e+08 | ... Q6: ='rNPV Model'!Q20 -> 83374564
A7: Unrisked unlevered free cash flow (pre-terminal) | C7: ='rNPV Model'!C32 -> -48000000 | D7: ='rNPV Model'!D32 -> -19053458 | E7: ='rNPV Model'!E32 -> 12170059 | F7: ='rNPV Model'!F32 -> -26016633 | G7: ='rNPV Model'!G32 -> -17944989 | H7: ='rNPV Model'!H32 -> 30588072 | I7: ='rNPV Model'!I32 -> 33557154 | J7: ='rNPV Model'!J32 -> 35359811 | ... Q7: ='rNPV Model'!Q32 -> 24370385
A9: TERMINAL VALUE (post-2040, reflecting exclusivity erosion)
A10: Terminal growth rate (post-2040, in perpetuity) | C10: -0.03 | D10: Negative growth reflects continued volume/price erosion after 2037 exclusivity expiry; biologic manufacturing complexity limits (but does not eliminate) biosimilar entry risk vs. small-molecule patent cliffs.
A11: WACC (linked from Cover tab) | C11: =INDEX('Cover & Assumptions'!$B$21:$D$21,'Cover & Assumptions'!$B$43) -> 0.15
A12: Terminal value @ end of 2040 (Gordon growth on final-year UFCF) | C12: =Q7*(1+C10)/(C11-C10) -> 1.313293e+08
A14: DISCOUNTING
A15: Discount period (years) | C15: ='rNPV Model'!C38 -> 0.47945205 | D15: ='rNPV Model'!D38 -> 1.4794521 | E15: ='rNPV Model'!E38 -> 2.4821918 | F15: ='rNPV Model'!F38 -> 3.4821918 | G15: ='rNPV Model'!G38 -> 4.4821918 | H15: ='rNPV Model'!H38 -> 5.4821918 | I15: ='rNPV Model'!I38 -> 6.4849315 | J15: ='rNPV Model'!J38 -> 7.4849315 | ... Q15: ='rNPV Model'!Q38 -> 14.490411
A16: Discount factor @ WACC | C16: =1/(1+C11)^C15 -> 0.93518664 | D16: =1/(1+C11)^D15 -> 0.81320578 | E16: =1/(1+C11)^E15 -> 0.70686474 | F16: =1/(1+C11)^F15 -> 0.61466499 | G16: =1/(1+C11)^G15 -> 0.5344913 | H16: =1/(1+C11)^H15 -> 0.46477504 | I16: =1/(1+C11)^I15 -> 0.40399749 | J16: =1/(1+C11)^J15 -> 0.35130216 | K16: =1/(1+C11)^K15 -> 0.30548014 | L16: =1/(1+C11)^L15 -> 0.2656349 | M16: =1/(1+C11)^M15 -> 0.23089844 | N16: =1/(1+C11)^N15 -> 0.20078126 | O16: =1/(1+C11)^O15 -> 0.1745924 | P16: =1/(1+C11)^P15 -> 0.15181947 | Q16: =1/(1+C11)^Q15 -> 0.13196639
A17: PV of unrisked free cash flow | C17: =C7*C16 -> -44888959 | D17: =D7*D16 -> -15494382 | E17: =E7*E16 -> 8602585.5 | F17: =F7*F16 -> -15991513 | G17: =G7*G16 -> -9591440.6 | H17: =H7*H16 -> 14216573 | I17: =I7*I16 -> 13557006 | J17: =J7*J16 -> 12421978 | ... Q17: =Q7*Q16 -> 3216071.8
A18: PV of terminal value | C18: =C12*Q16 -> 17331054
A20: DCF SUMMARY & IMPLIED PRICE TARGET (unrisked / success case)
A21: Sum of PV, explicit FCF (2026-2040) | C21: =SUM(C17:Q17) -> 10844065
A22: (+) PV of terminal value | C22: =C18 -> 17331054
A23: Enterprise value (DCF, unrisked) | C23: =C21+C18 -> 28175119
A24: (+) Cash & equivalents (pro forma, 30-Apr-26) | C24: ='Balance Sheet & Runway'!$E$5 -> 107300000
A25: (-) Total debt (face value) | C25: =-'Balance Sheet & Runway'!$B$11 -> -50000000
A26: Equity value (DCF basis) | C26: =C23+C24+C25 -> 85475119
A27: Fully-diluted shares outstanding (est.) | C27: ='Balance Sheet & Runway'!$B$40 -> 2962278
A28: IMPLIED PRICE TARGET — DCF METHOD (success case, unrisked) | C28: =C26/C27 -> 28.854523
A29: Implied probability-weighted read-through: rNPV price / DCF price | C29: ='rNPV Model'!$C$50/C28 -> 0.65379026 | D29: A rough cross-check: this ratio should sit near the overall probability-of-success assumption if the two models are internally consistent (rNPV ≈ DCF x PoS, before cash/debt/share-count differences wash out).
A31: Sensitivity reminder: this DCF is NOT a base-case fair value — it assumes TA-ERT succeeds commercially exactly as modeled, with no regulatory or execution risk discount. Use it as the ceiling case; use the rNPV tab as the probability-weighted 'fair value' estimate; use the Relative Valuation tab as a market-based cross-check.

Sheet Relative Valuation
A1: RELATIVE VALUATION — EV / PEAK-SALES MULTIPLE, DERIVED FROM PEERS
A2: Rebuilt 18-Jul-2026 to replace an earlier, cruder version of this tab (which had simply divided an assumed Zevra-like total market cap by SPRB's own small share count). This version instead derives an actual EV/Peak-Sales multiple from a true peer and applies it to SPRB's OWN modeled peak revenue — a proper relative valuation, not a share-count artifact.
A4: PEER SET AND WHY EACH ONE IS (OR ISN'T) USED FOR A MULTIPLE
A5: Company | B5: Mkt Cap | C5: Cash | D5: EV | E5: Peak sales est. (single asset) | F5: Used for multiple?
A6: Zevra Therapeutics (ZVRA) | B6: 790000000 | C6: 236800000 | D6: =B6-C6 -> 553200000 | E6: 165000000 | F6: YES — primary anchor | G6: Commercial-stage, single-asset (MIPLYFFA/arimoclomol for Niemann-Pick Type C), ultra-rare, small patient pool, CHRONIC/recurring daily dosing -- the closest true economic analog to TA-ERT's revenue durability (a steady annuity once patients are on drug, not a one-time cure). Peak sales range $150-180mm per Street estimates (midpoint $165mm used); current run-rate still ramping (~$98mm annualized in Q1-26). Debt-free as of Q1-26.
A7: Ultragenyx Pharmaceutical (RARE) / UX111 | B7: $2.1-2.3bn (whole co.) | C7: $534mm (Q1-26) | D7: n/a -- see note | E7: $150mm (Leerink); wide Street range $150mm-$1bn | F7: NO -- context only | G7: Excluded as a multiple source for two reasons: (1) Ultragenyx is a diversified commercial company (4 approved drugs generating ~$136mm/quarter) plus a ~$1.2bn royalty-monetization liability -- there is no clean way to isolate the EV attributable to UX111 alone; (2) UX111 is a ONE-TIME gene therapy. Its 'peak sales' figure reflects a front-loaded wave of one-time dosing that DECAYS once the diagnosed backlog is treated, unlike an ERT such as TA-ERT, which re-doses the same patients indefinitely and can sustain 'peak' revenue for a decade or more. A gene-therapy peak-sales multiple is therefore not directly transferable to a recurring-dose ERT -- using it would systematically overstate TA-ERT's value per dollar of peak sales, or understate it, depending on duration assumptions; it is genuinely ambiguous, so we exclude it from the multiple and use it only as an epidemiology/pricing sanity check (Leerink's 3,000-5,000 patient global estimate for the sister MPS IIIA subtype is a useful cross-check on our own MPS IIIB patient assumptions).
A9: IMPLIED EV / PEAK-SALES MULTIPLE (Zevra-derived)
A10: Zevra peak-sales estimate range used | B10: 150000000 | C10: Low | D10: 180000000 | E10: High
A11: Implied EV / Peak-Sales multiple | B11: =$D$6/D10 -> 3.0733333 | C11: =$D$6/$E$6 -> 3.3527273 | D11: =$D$6/B10 -> 3.688 | F11: Left = using Zevra's HIGH peak-sales estimate ($180mm) -> LOWER multiple (~3.1x). Right = using Zevra's LOW peak-sales estimate ($150mm) -> HIGHER multiple (~3.7x). Base case below uses the $165mm midpoint -> ~3.35x.
A12: Base-case multiple (midpoint peak sales) | B12: =$D$6/$E$6 -> 3.3527273
A14: APPLIED TO SPRUCE BIOSCIENCES' OWN PROJECTED PEAK REVENUE
A15: Peak revenue figures below are read from the rNPV Model tab's own revenue build (row 20), captured by toggling the Cover tab's scenario selector through Base and Bull and recording the resulting maximum annual revenue. These are a manual snapshot (like the Price Target Summary tab's scenario log), not a live formula, because Excel/LibreOffice cannot evaluate two scenario states of the same workbook simultaneously -- re-run and update if you change any epidemiology/pricing assumption.
A16: Scenario | B16: SPRB peak revenue (own model) | C16: x Low multiple (3.1x) | D16: x Base multiple (3.4x) | E16: x High multiple (3.7x)
A17: Base case (Cover tab scenario = 2) | B17: 128400000 | C17: =B17*$B$11 -> 394616000 | D17: =B17*$B$12 -> 4.3049018e+08 | E17: =B17*$D$11 -> 473539200 | F17: Peak revenue $128.4mm occurs in 2036 in the Base-case rNPV run.
A18: Bull case (Cover tab scenario = 3) | B18: 321300000 | C18: =B18*$B$11 -> 987462000 | D18: =B18*$B$12 -> 1.0772313e+09 | E18: =B18*$D$11 -> 1184954400 | F18: Peak revenue $321.3mm occurs in 2036 in the Bull-case rNPV run.
A20: IMPLIED EQUITY VALUE & PRICE TARGET (Base-multiple column only, for clarity)
A21: Implied EV -- Base SPRB revenue x Base multiple | B21: =D17 -> 4.3049018e+08
A22: Implied EV -- Bull SPRB revenue x Base multiple | B22: =D18 -> 1.0772313e+09
A23: (+) Cash & equivalents (pro forma, 30-Apr-26) | B23: ='Balance Sheet & Runway'!$E$5 -> 107300000
A24: (-) Total debt (face value) | B24: =-'Balance Sheet & Runway'!$B$11 -> -50000000
A25: Fully-diluted shares outstanding (est.) | B25: ='Balance Sheet & Runway'!$B$40 -> 2962278
A26: IMPLIED PRICE TARGET -- Base SPRB revenue, Zevra multiple | B26: =(B21+B23+B24)/B25 -> 164.66725
A27: IMPLIED PRICE TARGET -- Bull SPRB revenue, Zevra multiple | B27: =(B22+B23+B24)/B25 -> 382.99284
A29: SPRUCE BIOSCIENCES — CURRENT MARKET VALUATION (reference)
A30: SPRB stock price | B30: ='Cover & Assumptions'!$B$11 -> 43.54
A31: Implied market capitalization (reported shares) | B31: ='Cover & Assumptions'!$B$13 -> 1.1983418e+08
A33: Read this against the DCF tab: this method's Base-case output comes out HIGHER than the DCF success-case price target ($28.85), even though both use the same underlying revenue projection. That gap is itself informative, not a mistake: a 3.1-3.7x peak-sales multiple derived from how the market actually prices Zevra implies a materially lower effective discount rate (and/or more credited growth beyond the explicit 2040 horizon) than this model's 15% WACC + no-terminal-value DCF construction. Neither number is 'right' -- they encode different assumptions about duration and cost of capital, and comparing them is the useful exercise, not picking a winner.

Sheet Price Target Summary
A1: PRICE TARGET SUMMARY
A2: Blends the rNPV (probability-weighted fair value), DCF (unrisked success case / ceiling), and relative-valuation cross-check. Current price and every method below update automatically when you change the scenario selector on the Cover tab.
A4: CURRENT MARKET REFERENCE
A5: SPRB current stock price | B5: ='Cover & Assumptions'!$B$11 -> 43.54
A6: Analyst consensus price target (Street, for reference only) | B6: 160 | C6: Updated 18-Jul-2026. 11 sell-side analysts per MarketBeat: 8 Buy / 2 Hold / 1 Sell, average target ~$160-163, range $120-259. Recent notes: B. Riley (Buy, $160, new); JonesTrading (Buy, $135, explicitly credits PRV cash flow); Craig-Hallum (Buy, $140); Citizens JMP (Market Outperform, cut $170->$150 in May-26, was as high as $259 shortly after the Oct-25 BTD); HC Wainwright (Buy, cut $200->$150 in Jun-26); Leerink (Outperform, $160, explicitly cites SPRB trading below 1.0x their estimated peak-revenue opportunity); Guggenheim (Buy, initiated Jun-26). Weiss Ratings (a quantitative, non-underwriter rating service) is the lone Sell (D-) -- notable because it is the one voice without a banking relationship to the company. Leerink, Guggenheim and Oppenheimer were joint book-running managers on Spruce equity offerings -- a real conflict of interest worth weighing against their own Buy ratings.
A8: VALUATION METHOD OUTPUTS
A9: Method | B9: Implied price / share | C9: vs. current price | D9: Weight | E9: Weighted contribution | F9: What it represents
A10: rNPV (risk-adjusted fair value) | B10: ='rNPV Model'!$C$50 -> 18.864806 | C10: =B10/B5-1 -> -0.56672471 | D10: 0.55 | E10: =B10*D10 -> 10.375643 | F10: Probability-weights the full regulatory/commercial risk into a single 'what is this worth today' number. Weighted most heavily as the most defensible base-case method for a pre-approval, single-asset biotech.
A11: DCF (unrisked success case / ceiling) | B11: ='DCF Model'!$C$28 -> 28.854523 | C11: =B11/B5-1 -> -0.33728702 | D11: 0.25 | E11: =B11*D11 -> 7.2136308 | F11: Answers 'what is it worth if everything goes right' — useful as an upper anchor and for understanding how much of the current price is regulatory optionality vs. intrinsic operating value.
A12: Relative valuation (EV/Peak-Sales, Zevra-derived, Base case) | B12: ='Relative Valuation'!$B$26 -> 164.66725 | C12: =B12/B5-1 -> 2.7819764 | D12: 0.2 | E12: =B12*D12 -> 32.933451 | F12: Rebuilt 18-Jul-2026: now a proper EV/Peak-Sales multiple (~3.35x, derived from how the market actually prices Zevra Therapeutics against its own peak-sales estimate) applied to SPRB's own modeled peak revenue -- not a share-count artifact. Still the most assumption-sensitive of the three methods (peak revenue AND the peer multiple are both estimates), but now at least it is a real multiple applied to a real projection.
A13: BLENDED PRICE TARGET | B13: =SUM(E10:E12) -> 50.522725 | C13: =B13/B5-1 -> 0.16037494 | D13: =SUM(D10:D12) -> 1 | F13: Weights are editable blue-shaded assumptions (should sum to 100%) — adjust to reflect your own conviction across methods.
A15: SCENARIO SENSITIVITY (rNPV price target by scenario)
A16: Note: manually step the scenario selector (Cover tab, cell B43) through 1/2/3 and record the rNPV price target below — kept as a manual log since Excel/LibreOffice formulas cannot self-iterate a single input cell across three states simultaneously.
A17: Scenario | B17: rNPV price target | C17: DCF price target | D17: Notes
A18: 1 = Bear (Low case) | D18: Set Cover tab B43 to this value, recalculate, then paste the resulting rNPV/DCF price targets here as static values for a quick 3-point range.
A19: 2 = Base | D19: Set Cover tab B43 to this value, recalculate, then paste the resulting rNPV/DCF price targets here as static values for a quick 3-point range.
A20: 3 = Bull (High case) | D20: Set Cover tab B43 to this value, recalculate, then paste the resulting rNPV/DCF price targets here as static values for a quick 3-point range.
A22: KEY SENSITIVITIES (directional — what moves the price target most)
A23: • Peak treated-patient count and diagnosed prevalent pool: the single largest swing factor. Base case assumes ~250 peak patients (US+EU5); a KOL-informed epidemiology update could move this ±50% or more.
A24: • Annual net price per patient: base case $500k. Payer pushback on an ICV/Ommaya-delivered ERT (vs. IV/SC competitors) is a real risk not separately probability-weighted here.
A25: • Overall probability of commercial success (base 78%): reflects strong regulatory de-risking (Breakthrough Therapy Designation, FDA alignment on HS biomarker, BLA-ready with no further studies required) — but a negative confirmatory-trial readout post-accelerated-approval remains a tail risk.
A26: • Discount rate (WACC, base 15%): reflects micro-cap, single-asset risk. A large-cap-style 8-10% WACC (arguably too generous for this profile) would materially increase all outputs.
A27: • BioMarin royalty/milestone economics (10% royalty + up to $122.5mm milestones): fixed by contract, meaningfully caps SPRB's own economics versus a fully-owned asset.
A28: • Further dilution: any additional capital raise (likely, given the runway math on the Balance Sheet tab) will increase the share count and mechanically reduce per-share value versus this estimate.

Sheet Sources
A1: SOURCES & DATA PROVENANCE
A3: PRIMARY SOURCES USED IN THIS MODEL
A4: • SEC EDGAR — Spruce Biosciences filer page (CIK 0001683553): https://www.sec.gov/edgar/browse/?CIK=1683553&owner=exclude
A5: • 8-K Ex-99.2, TA-ERT investor conference call deck, filed 15-Apr-2025 (BioMarin license terms, capital structure as of 31-Dec-2024, MPS ERT pricing/sales benchmark table): https://www.sec.gov/Archives/edgar/data/1683553/000095017025053944/sprb-ex99_2.htm
A6: • Q1 2026 earnings release, 13-May-2026 (cash, balance sheet, opex, pro forma post-offering cash) — BusinessWire / BioSpace / StockTitan reprints
A7: • Q1 2026 10-Q (share count as of 31-Mar-2026; Avenue Capital loan terms) — SEC EDGAR / StockTitan
A8: • 8-K, reverse stock split announcement, Jul-2025 (1-for-75 ratio, share count before/after): https://www.sec.gov/Archives/edgar/data/1683553/000095017025098340/sprb-ex99_1.htm
A9: • FY2023 and FY2024 quarterly earnings releases (tildacerfont CAH trial history — CAHmelia-203/204, CAHptain-205)
A10: • Fintel.io / StockTitan / OpenInsider — institutional ownership and Form 4 insider transaction summaries
A11: • StockAnalysis.com, Morningstar, Investing.com, MarketScreener, CNN Markets — SPRB stock price, analyst ratings/price targets, 52-week range
A12: • MacroTrends, PitchBook, CompaniesMarketCap, Yahoo Finance (ES) — peer company market capitalizations (BMRN, RARE, DNLI, RGNX, ZVRA)
A13: • Merlintrader.com research note (8-Jul-2026) — Ultragenyx UX111 (MPS IIIA) regulatory timeline
... A23: This workbook is an analytical working file prepared for research/educational purposes. It is not investment advice, a research report intended for distribution, or a solicitation to buy or sell any security. All estimates, especially epidemiology, pricing, and share-count figures, carry wide uncertainty bands and should be independently verified before being relied upon. Micro-cap, single-asset, pre-revenue biopharmaceutical equities carry substantial risk of loss, including total loss of capital.
